Workbook
Name Month2: c_Calculations!$T$2:$GQ$2
Name sht_Contents: 'Front Sheet'!$A$1
Name sht_sysCheck: sysCheck!$A$1
Name sysAlert: sysCheck!$L$25
Name sysCheck: sysCheck!$K$25
Name sysCheckText: sysCheck!$K$17
Name sht_Contents: o_DCF!$A$1
Name sht_Contents: o_Dashboard!$A$1

Sheet Front Sheet
B1: =i_Setup!$M$13&" Financial Projection"
B2: =MID(CELL("filename",C1),FIND("]",CELL("filename",C1))+1,256)
B4: Tab Check | H4: LINK TO FRONT SHEET
B5: =SUM(B$8:B103) | C5: =SUM(C$8:C103) | H5: =sysCheckText
B6: Err | C6: Alert
D8: =Heading1 | E8: Disclaimer
D27: =Heading1 | E27: Instructions
E29: 2.1 | H29: The only tabs that should be populated by the user are the input tabs. The calculation tab uses the user-defined inputs to produce the projection outputs which are presented in the output tabs.
E31: 2.2 | H31: The user should start off my populating the 'i_Setup' tab followed by the 'i_Actuals' (if applicable) and 'i_Assumptions' tabs.
E33: 2.3 | H33: The input cells in the input sheets that are required to be populated are formatted as follows:
E35: 2.4 | H35: The following signage conventions apply throughout the model. Most Input cells contain data validations to help users populate assumption in line with the below conventions
H36: · Revenues (+) and expenses (-)
H37: · Assets (+), Liabilities (-) and Equity (-)
H38: · Cash Inflows (+) and cash outflows (-)
E40: 2.5 | H40: Most of the reference or input cells contain input messages with details on the particular item or on how the input cell should be populated. Hover over the cells to see the input message
E51: 2.6 | H51: The projection model contains error checks and warnings throughout the tabs. The workbook and tab checks status are displayed at the top left hand corner of each tab and summarised in the 'sysChecks' tab.
H52: The status bar is set out as follows:
H54: All file checks & alerts OK | I54: - No errors or alerts
H55: File: 1 alert | I55: - Alert in input cells present
H56: File: 1 error | I56: - Errors in input cells present
E58: 2.7 | H58: To add additional categories for most items (except direct staff, fixed assets and borrowings), this can be done by adding rows below the last category and applying this consistently across the
H59: model starting from 'i_Setup' tab and moving right to 'o_Fin Stats'. Please ensure formulas in total rows are also updated to include the additional categories. For other categories, e.g. fixed
H60: assets and borrowings you need to make sure the additional calculations (e.g. inventories, depreciation, interest) are also replicated and linked to the financial statements.
D63: =Heading1 | E63: Contents
D103: END OF WORKSHEET

Sheet sysCheck
B1: =i_Setup!$M$13&" Financial Projection"
B2: =MID(CELL("filename",C1),FIND("]",CELL("filename",C1))+1,256)
B4: Tab Check | H4: LINK TO FRONT SHEET
B5: =SUM(B$8:B49) | C5: =SUM(C$8:C49) | H5: =sysCheckText
B6: Err | C6: Alert
D8: =Heading1 | E8: Check Text
H10: # of checks triggered | K10: =sysCheck&IF(sysCheck>1," errors", " error")
H11: # of alerts triggered | K11: =sysAlert&IF(sysAlert>1," alerts", " alert")
H13: Wording for triggered check | K13: =IF(sysCheck=0,"",K10)
H14: Wording for triggered alert | K14: =IF(sysAlert=0,"",K11)
H15: Concatenated wording for check/alert | K15: =IF(AND(sysCheck>0,sysAlert>0),"File: "&K13& " and " &K14,"File: "&K13&K14)
H17: Check/Alert Wording | K17: =IF(AND(sysCheck=0,sysAlert=0),"All file checks & alerts OK",K15)
D19: =Heading1 | E19: Model checks
E21: =Heading2 | F21: Master check
K23: Model error | L23: Model alert
H25: Model Error Check | K25: =SUM(K29:K46) | L25: =SUM(L29:L46)
E27: =Heading2 | F27: Individual error checks and alerts
K28: B5 | L28: C5
H29: System sheets
H30: sysCheck | K30: =INDIRECT("'"&$H30&"'!"&K$28) | L30: =INDIRECT("'"&$H30&"'!"&L$28)
H31: Front Sheet | K31: =INDIRECT("'"&$H31&"'!"&K$28) | L31: =INDIRECT("'"&$H31&"'!"&L$28)
H33: Input sheets
H34: i_Setup | K34: =INDIRECT("'"&$H34&"'!"&K$28) | L34: =INDIRECT("'"&$H34&"'!"&L$28)
H35: i_Actuals | K35: =INDIRECT("'"&$H35&"'!"&K$28) | L35: =INDIRECT("'"&$H35&"'!"&L$28)
H36: i_Assumptions | K36: =INDIRECT("'"&$H36&"'!"&K$28) | L36: =INDIRECT("'"&$H36&"'!"&L$28)
H38: Calculation sheets
H39: c_Calculations | K39: =INDIRECT("'"&$H39&"'!"&K$28) | L39: =INDIRECT("'"&$H39&"'!"&L$28)
H41: Output sheets
H42: o_Dashboard | K42: =INDIRECT("'"&$H42&"'!"&K$28) | L42: =INDIRECT("'"&$H42&"'!"&L$28)
H43: o_Fin Stats | K43: =INDIRECT("'"&$H43&"'!"&K$28) | L43: =INDIRECT("'"&$H43&"'!"&L$28)
H44: o_DCF | K44: =INDIRECT("'"&$H44&"'!"&K$28) | L44: =INDIRECT("'"&$H44&"'!"&L$28)
D49: END OF WORKSHEET

Sheet i_Setup
B1: =i_Setup!$M$13&" Financial Projection"
B2: =MID(CELL("filename",C1),FIND("]",CELL("filename",C1))+1,256)
B4: Tab Check | H4: LINK TO FRONT SHEET
B5: =SUM(B$9:B130) | C5: =SUM(C$9:C130) | H5: =sysCheckText
B6: Err | C6: Alert
D9: =Heading1 | E9: Setup Inputs
E11: =Heading2 | F11: General Inputs
G13: 1 | H13: Name of company | I13: Text | M13: ABC Ship Management Ltd
G16: =MAX(G$9:G15)+1 | H16: Currency | I16: List | M16: USD
G19: =MAX(G$9:G18)+1 | H19: Timeline Start Year | I19: List | M19: 2024
G22: =MAX(G$9:G21)+1 | H22: First Projection Year | I22: List | M22: 2024
G25: =MAX(G$9:G23)+1 | H25: First Projection Month | I25: List | M25: 6 | T25: =IFERROR(DATE(M22,M25,1),0) | U25: =EOMONTH(T25,0)
U26: =IFERROR(EOMONTH(T25,-1),0)
E28: =Heading2 | F28: Naming Inputs
G30: =MAX(G3:G$29)+1 | H30: Types of Ships
M31: Name | P31: Sales Tax
H32: ="Ship Type "&T32&" (ST"&T32&")" | I32: Text / List | M32: Container Ships | P32: Yes | T32: 1 | U32: =IF(M32<>"","ST"&T32&" - "&M32,"ST"&T32&" - "&"N/A")
H33: ="Ship Type "&T33&" (ST"&T33&")" | I33: Text / List | M33: Bulk Carriers | P33: Yes | T33: =T32+1 | U33: =IF(M33<>"","ST"&T33&" - "&M33,"ST"&T33&" - "&"N/A")
H34: ="Ship Type "&T34&" (ST"&T34&")" | I34: Text / List | M34: Tankers | P34: Yes | T34: =T33+1 | U34: =IF(M34<>"","ST"&T34&" - "&M34,"ST"&T34&" - "&"N/A")
H35: ="Ship Type "&T35&" (ST"&T35&")" | I35: Text / List | M35: Ro-Ro Vessels | P35: Yes | T35: =T34+1 | U35: =IF(M35<>"","ST"&T35&" - "&M35,"ST"&T35&" - "&"N/A")
H36: ="Ship Type "&T36&" (ST"&T36&")" | I36: Text / List | M36: LNG Carriers | P36: Yes | T36: =T35+1 | U36: =IF(M36<>"","ST"&T36&" - "&M36,"ST"&T36&" - "&"N/A")
H37: ="Ship Type "&T37&" (ST"&T37&")" | I37: Text / List | M37: Bulk Carrier | P37: Yes | T37: =T36+1 | U37: =IF(M37<>"","ST"&T37&" - "&M37,"ST"&T37&" - "&"N/A")
H38: ="Ship Type "&T38&" (ST"&T38&")" | I38: Text / List | T38: =T37+1 | U38: =IF(M38<>"","ST"&T38&" - "&M38,"ST"&T38&" - "&"N/A")
H39: ="Ship Type "&T39&" (ST"&T39&")" | I39: Text / List | T39: =T38+1 | U39: =IF(M39<>"","ST"&T39&" - "&M39,"ST"&T39&" - "&"N/A")
H40: ="Ship Type "&T40&" (ST"&T40&")" | I40: Text / List | T40: =T39+1 | U40: =IF(M40<>"","ST"&T40&" - "&M40,"ST"&T40&" - "&"N/A")
H41: ="Ship Type "&T41&" (ST"&T41&")" | I41: Text / List | T41: =T40+1 | U41: =IF(M41<>"","ST"&T41&" - "&M41,"ST"&T41&" - "&"N/A")
G44: =MAX(G$9:G43)+1 | H44: Staff costs
M45: Name
H46: ="Direct Staff Category "&T46 | I46: Text | M46: Crew - Captain | T46: 1 | U46: =IF(M46<>"","DS"&T46&" - "&M46,"DS"&T46&" - "&"N/A")
H47: ="Direct Staff Category "&T47 | I47: Text | M47: Crew - Officers | T47: =T46+1 | U47: =IF(M47<>"","DS"&T47&" - "&M47,"DS"&T47&" - "&"N/A")
H48: ="Direct Staff Category "&T48 | I48: Text | M48: Crew - Engineers | T48: =T47+1 | U48: =IF(M48<>"","DS"&T48&" - "&M48,"DS"&T48&" - "&"N/A")
H49: ="Direct Staff Category "&T49 | I49: Text | M49: Crew - Deck Cadets | T49: =T48+1 | U49: =IF(M49<>"","DS"&T49&" - "&M49,"DS"&T49&" - "&"N/A")
H50: ="Direct Staff Category "&T50 | I50: Text | M50: Crew - Engine Cadets | T50: =T49+1 | U50: =IF(M50<>"","DS"&T50&" - "&M50,"DS"&T50&" - "&"N/A")
H51: ="Direct Staff Category "&T51 | I51: Text | M51: Crew - Other | T51: =T50+1 | U51: =IF(M51<>"","DS"&T51&" - "&M51,"DS"&T51&" - "&"N/A")
H52: ="Direct Staff Category "&T52 | I52: Text | T52: =T51+1 | U52: =IF(M52<>"","DS"&T52&" - "&M52,"DS"&T52&" - "&"N/A")
H53: ="Direct Staff Category "&T53 | I53: Text | T53: =T52+1 | U53: =IF(M53<>"","DS"&T53&" - "&M53,"DS"&T53&" - "&"N/A")
H55: ="Non-Direct Staff Category "&T55 | I55: Text | M55: Management | T55: 1 | U55: =IF(M55<>"","NS"&T55&" - "&M55,"NS"&T55&" - "&"N/A")
H56: ="Non-Direct Staff Category "&T56 | I56: Text | M56: Admin | T56: =T55+1 | U56: =IF(M56<>"","NS"&T56&" - "&M56,"NS"&T56&" - "&"N/A")
H57: ="Non-Direct Staff Category "&T57 | I57: Text | M57: Operations | T57: =T56+1 | U57: =IF(M57<>"","NS"&T57&" - "&M57,"NS"&T57&" - "&"N/A")
H58: ="Non-Direct Staff Category "&T58 | I58: Text | M58: Sales | T58: =T57+1 | U58: =IF(M58<>"","NS"&T58&" - "&M58,"NS"&T58&" - "&"N/A")
...

Sheet i_Actuals
B1: =i_Setup!$M$13&" Financial Projection" | K1: Start date | M1: =DATE(i_Setup!$M$19,1,1) | N1: =M2+1 | O1: =N2+1 | P1: =O2+1 | Q1: =P2+1 | T1: =DATE(i_Setup!$M$19,1,1) | U1: =T2+1 | V1: =U2+1 | W1: =V2+1 | X1: =W2+1 | Y1: =X2+1 | Z1: =Y2+1 | AA1: =Z2+1 | AB1: =AA2+1 | ... CA1: =BZ2+1
B2: =MID(CELL("filename",C1),FIND("]",CELL("filename",C1))+1,256) | K2: End date | M2: =EDATE(M$1,12)-1 | N2: =EDATE(N$1,12)-1 | O2: =EDATE(O$1,12)-1 | P2: =EDATE(P$1,12)-1 | Q2: =EDATE(Q$1,12)-1 | T2: =EDATE(T$1,1)-1 | U2: =EDATE(U$1,1)-1 | V2: =EDATE(V$1,1)-1 | W2: =EDATE(W$1,1)-1 | X2: =EDATE(X$1,1)-1 | Y2: =EDATE(Y$1,1)-1 | Z2: =EDATE(Z$1,1)-1 | AA2: =EDATE(AA$1,1)-1 | ... CA2: =EDATE(CA$1,1)-1
K3: Timeline | M3: ANNUAL | N3: ANNUAL | O3: ANNUAL | P3: ANNUAL | Q3: ANNUAL | T3: MONTHLY | U3: MONTHLY | V3: MONTHLY | W3: MONTHLY | X3: MONTHLY | Y3: MONTHLY | Z3: MONTHLY | AA3: MONTHLY | AB3: MONTHLY | AC3: MONTHLY | AD3: MONTHLY | AE3: MONTHLY | AF3: MONTHLY | AG3: MONTHLY | AH3: MONTHLY | AI3: MONTHLY | AJ3: MONTHLY | AK3: MONTHLY | AL3: MONTHLY | AM3: MONTHLY | AN3: MONTHLY | AO3: MONTHLY | AP3: MONTHLY | AQ3: MONTHLY | AR3: MONTHLY | AS3: MONTHLY | AT3: MONTHLY | AU3: MONTHLY | AV3: MONTHLY | AW3: MONTHLY | AX3: MONTHLY | AY3: MONTHLY | AZ3: MONTHLY | BA3: MONTHLY | BB3: MONTHLY | BC3: MONTHLY | BD3: MONTHLY | BE3: MONTHLY | BF3: MONTHLY | BG3: MONTHLY | BH3: MONTHLY | BI3: MONTHLY | BJ3: MONTHLY | BK3: MONTHLY | BL3: MONTHLY | BM3: MONTHLY | BN3: MONTHLY | BO3: MONTHLY | BP3: MONTHLY | BQ3: MONTHLY | BR3: MONTHLY | BS3: MONTHLY | BT3: MONTHLY | BU3: MONTHLY | BV3: MONTHLY | BW3: MONTHLY | BX3: MONTHLY | BY3: MONTHLY | BZ3: MONTHLY | CA3: MONTHLY
B4: Tab Check | H4: LINK TO FRONT SHEET | K4: Year index | M4: 1 | N4: =M$4+1 | O4: =N$4+1 | P4: =O$4+1 | Q4: =P$4+1 | T4: =YEAR(T2)-(YEAR($M$1)-1) | U4: =YEAR(U2)-(YEAR($M$1)-1) | V4: =YEAR(V2)-(YEAR($M$1)-1) | W4: =YEAR(W2)-(YEAR($M$1)-1) | X4: =YEAR(X2)-(YEAR($M$1)-1) | Y4: =YEAR(Y2)-(YEAR($M$1)-1) | Z4: =YEAR(Z2)-(YEAR($M$1)-1) | AA4: =YEAR(AA2)-(YEAR($M$1)-1) | ... CA4: =YEAR(CA2)-(YEAR($M$1)-1)
B5: =SUM(B$9:B157) | C5: =SUM(C$9:C157) | H5: =sysCheckText | K5: Relative period | M5: 1 | N5: 1 | O5: 1 | P5: 1 | Q5: 1 | T5: =MONTH(T2) | U5: =MONTH(U2) | V5: =MONTH(V2) | W5: =MONTH(W2) | X5: =MONTH(X2) | Y5: =MONTH(Y2) | Z5: =MONTH(Z2) | AA5: =MONTH(AA2) | ... CA5: =MONTH(CA2)
B6: Err | C6: Alert | K6: Period index | M6: 1 | N6: =M$6+1 | O6: =N$6+1 | P6: =O$6+1 | Q6: =P$6+1 | T6: 1 | U6: =T$6+1 | V6: =U$6+1 | W6: =V$6+1 | X6: =W$6+1 | Y6: =X$6+1 | Z6: =Y$6+1 | AA6: =Z$6+1 | AB6: =AA$6+1 | ... CA6: =BZ$6+1
K7: Status | M7: =IF(M2<i_Setup!$U$25,"Actual","Forecast") | N7: =IF(N2<i_Setup!$U$25,"Actual","Forecast") | O7: =IF(O2<i_Setup!$U$25,"Actual","Forecast") | P7: =IF(P2<i_Setup!$U$25,"Actual","Forecast") | Q7: =IF(Q2<i_Setup!$U$25,"Actual","Forecast") | T7: =IF(T2<i_Setup!$U$25,"Actual","Forecast") | U7: =IF(U2<i_Setup!$U$25,"Actual","Forecast") | V7: =IF(V2<i_Setup!$U$25,"Actual","Forecast") | W7: =IF(W2<i_Setup!$U$25,"Actual","Forecast") | X7: =IF(X2<i_Setup!$U$25,"Actual","Forecast") | Y7: =IF(Y2<i_Setup!$U$25,"Actual","Forecast") | Z7: =IF(Z2<i_Setup!$U$25,"Actual","Forecast") | AA7: =IF(AA2<i_Setup!$U$25,"Actual","Forecast") | ... CA7: =IF(CA2<i_Setup!$U$25,"Actual","Forecast")
D9: =Heading1 | E9: Actuals
E11: =Heading2 | F11: Income Statement
G13: Total Revenue
H14: =i_Setup!U32 | I14: =i_Setup!$M$16 | M14: =SUMIF($T$4:$CA$4,M$4,$T14:$CA14) | N14: =SUMIF($T$4:$CA$4,N$4,$T14:$CA14) | O14: =SUMIF($T$4:$CA$4,O$4,$T14:$CA14) | P14: =SUMIF($T$4:$CA$4,P$4,$T14:$CA14) | Q14: =SUMIF($T$4:$CA$4,Q$4,$T14:$CA14)
H15: =i_Setup!U33 | I15: =i_Setup!$M$16 | M15: =SUMIF($T$4:$CA$4,M$4,$T15:$CA15) | N15: =SUMIF($T$4:$CA$4,N$4,$T15:$CA15) | O15: =SUMIF($T$4:$CA$4,O$4,$T15:$CA15) | P15: =SUMIF($T$4:$CA$4,P$4,$T15:$CA15) | Q15: =SUMIF($T$4:$CA$4,Q$4,$T15:$CA15)
H16: =i_Setup!U34 | I16: =i_Setup!$M$16 | M16: =SUMIF($T$4:$CA$4,M$4,$T16:$CA16) | N16: =SUMIF($T$4:$CA$4,N$4,$T16:$CA16) | O16: =SUMIF($T$4:$CA$4,O$4,$T16:$CA16) | P16: =SUMIF($T$4:$CA$4,P$4,$T16:$CA16) | Q16: =SUMIF($T$4:$CA$4,Q$4,$T16:$CA16)
H17: =i_Setup!U35 | I17: =i_Setup!$M$16 | M17: =SUMIF($T$4:$CA$4,M$4,$T17:$CA17) | N17: =SUMIF($T$4:$CA$4,N$4,$T17:$CA17) | O17: =SUMIF($T$4:$CA$4,O$4,$T17:$CA17) | P17: =SUMIF($T$4:$CA$4,P$4,$T17:$CA17) | Q17: =SUMIF($T$4:$CA$4,Q$4,$T17:$CA17)
H18: =i_Setup!U36 | I18: =i_Setup!$M$16 | M18: =SUMIF($T$4:$CA$4,M$4,$T18:$CA18) | N18: =SUMIF($T$4:$CA$4,N$4,$T18:$CA18) | O18: =SUMIF($T$4:$CA$4,O$4,$T18:$CA18) | P18: =SUMIF($T$4:$CA$4,P$4,$T18:$CA18) | Q18: =SUMIF($T$4:$CA$4,Q$4,$T18:$CA18)
H19: =i_Setup!U37 | I19: =i_Setup!$M$16 | M19: =SUMIF($T$4:$CA$4,M$4,$T19:$CA19) | N19: =SUMIF($T$4:$CA$4,N$4,$T19:$CA19) | O19: =SUMIF($T$4:$CA$4,O$4,$T19:$CA19) | P19: =SUMIF($T$4:$CA$4,P$4,$T19:$CA19) | Q19: =SUMIF($T$4:$CA$4,Q$4,$T19:$CA19)
H20: =i_Setup!U38 | I20: =i_Setup!$M$16 | M20: =SUMIF($T$4:$CA$4,M$4,$T20:$CA20) | N20: =SUMIF($T$4:$CA$4,N$4,$T20:$CA20) | O20: =SUMIF($T$4:$CA$4,O$4,$T20:$CA20) | P20: =SUMIF($T$4:$CA$4,P$4,$T20:$CA20) | Q20: =SUMIF($T$4:$CA$4,Q$4,$T20:$CA20)
H21: =i_Setup!U39 | I21: =i_Setup!$M$16 | M21: =SUMIF($T$4:$CA$4,M$4,$T21:$CA21) | N21: =SUMIF($T$4:$CA$4,N$4,$T21:$CA21) | O21: =SUMIF($T$4:$CA$4,O$4,$T21:$CA21) | P21: =SUMIF($T$4:$CA$4,P$4,$T21:$CA21) | Q21: =SUMIF($T$4:$CA$4,Q$4,$T21:$CA21)
H22: =i_Setup!U40 | I22: =i_Setup!$M$16 | M22: =SUMIF($T$4:$CA$4,M$4,$T22:$CA22) | N22: =SUMIF($T$4:$CA$4,N$4,$T22:$CA22) | O22: =SUMIF($T$4:$CA$4,O$4,$T22:$CA22) | P22: =SUMIF($T$4:$CA$4,P$4,$T22:$CA22) | Q22: =SUMIF($T$4:$CA$4,Q$4,$T22:$CA22)
H23: =i_Setup!U41 | I23: =i_Setup!$M$16 | M23: =SUMIF($T$4:$CA$4,M$4,$T23:$CA23) | N23: =SUMIF($T$4:$CA$4,N$4,$T23:$CA23) | O23: =SUMIF($T$4:$CA$4,O$4,$T23:$CA23) | P23: =SUMIF($T$4:$CA$4,P$4,$T23:$CA23) | Q23: =SUMIF($T$4:$CA$4,Q$4,$T23:$CA23)
G24: Total Revenue | I24: =i_Setup!$M$16 | M24: =SUM(M14:M23) | N24: =SUM(N14:N23) | O24: =SUM(O14:O23) | P24: =SUM(P14:P23) | Q24: =SUM(Q14:Q23) | T24: =SUM(T14:T23) | U24: =SUM(U14:U23) | V24: =SUM(V14:V23) | W24: =SUM(W14:W23) | X24: =SUM(X14:X23) | Y24: =SUM(Y14:Y23) | Z24: =SUM(Z14:Z23) | AA24: =SUM(AA14:AA23) | ... CA24: =SUM(CA14:CA23)
G26: Direct Staff Costs
H27: =i_Setup!U46 | I27: =i_Setup!$M$16 | M27: =SUMIF($T$4:$CA$4,M$4,$T27:$CA27) | N27: =SUMIF($T$4:$CA$4,N$4,$T27:$CA27) | O27: =SUMIF($T$4:$CA$4,O$4,$T27:$CA27) | P27: =SUMIF($T$4:$CA$4,P$4,$T27:$CA27) | Q27: =SUMIF($T$4:$CA$4,Q$4,$T27:$CA27)
H28: =i_Setup!U47 | I28: =i_Setup!$M$16 | M28: =SUMIF($T$4:$CA$4,M$4,$T28:$CA28) | N28: =SUMIF($T$4:$CA$4,N$4,$T28:$CA28) | O28: =SUMIF($T$4:$CA$4,O$4,$T28:$CA28) | P28: =SUMIF($T$4:$CA$4,P$4,$T28:$CA28) | Q28: =SUMIF($T$4:$CA$4,Q$4,$T28:$CA28)
H29: =i_Setup!U48 | I29: =i_Setup!$M$16 | M29: =SUMIF($T$4:$CA$4,M$4,$T29:$CA29) | N29: =SUMIF($T$4:$CA$4,N$4,$T29:$CA29) | O29: =SUMIF($T$4:$CA$4,O$4,$T29:$CA29) | P29: =SUMIF($T$4:$CA$4,P$4,$T29:$CA29) | Q29: =SUMIF($T$4:$CA$4,Q$4,$T29:$CA29)
H30: =i_Setup!U49 | I30: =i_Setup!$M$16 | M30: =SUMIF($T$4:$CA$4,M$4,$T30:$CA30) | N30: =SUMIF($T$4:$CA$4,N$4,$T30:$CA30) | O30: =SUMIF($T$4:$CA$4,O$4,$T30:$CA30) | P30: =SUMIF($T$4:$CA$4,P$4,$T30:$CA30) | Q30: =SUMIF($T$4:$CA$4,Q$4,$T30:$CA30)
H31: =i_Setup!U50 | I31: =i_Setup!$M$16 | M31: =SUMIF($T$4:$CA$4,M$4,$T31:$CA31) | N31: =SUMIF($T$4:$CA$4,N$4,$T31:$CA31) | O31: =SUMIF($T$4:$CA$4,O$4,$T31:$CA31) | P31: =SUMIF($T$4:$CA$4,P$4,$T31:$CA31) | Q31: =SUMIF($T$4:$CA$4,Q$4,$T31:$CA31)
H32: =i_Setup!U51 | I32: =i_Setup!$M$16 | M32: =SUMIF($T$4:$CA$4,M$4,$T32:$CA32) | N32: =SUMIF($T$4:$CA$4,N$4,$T32:$CA32) | O32: =SUMIF($T$4:$CA$4,O$4,$T32:$CA32) | P32: =SUMIF($T$4:$CA$4,P$4,$T32:$CA32) | Q32: =SUMIF($T$4:$CA$4,Q$4,$T32:$CA32)
H33: =i_Setup!U52 | I33: =i_Setup!$M$16 | M33: =SUMIF($T$4:$CA$4,M$4,$T33:$CA33) | N33: =SUMIF($T$4:$CA$4,N$4,$T33:$CA33) | O33: =SUMIF($T$4:$CA$4,O$4,$T33:$CA33) | P33: =SUMIF($T$4:$CA$4,P$4,$T33:$CA33) | Q33: =SUMIF($T$4:$CA$4,Q$4,$T33:$CA33)
H34: =i_Setup!U53 | I34: =i_Setup!$M$16 | M34: =SUMIF($T$4:$CA$4,M$4,$T34:$CA34) | N34: =SUMIF($T$4:$CA$4,N$4,$T34:$CA34) | O34: =SUMIF($T$4:$CA$4,O$4,$T34:$CA34) | P34: =SUMIF($T$4:$CA$4,P$4,$T34:$CA34) | Q34: =SUMIF($T$4:$CA$4,Q$4,$T34:$CA34)
G35: Total Direct Staff Costs | I35: =i_Setup!$M$16 | M35: =SUM(M27:M34) | N35: =SUM(N27:N34) | O35: =SUM(O27:O34) | P35: =SUM(P27:P34) | Q35: =SUM(Q27:Q34) | T35: =SUM(T27:T34) | U35: =SUM(U27:U34) | V35: =SUM(V27:V34) | W35: =SUM(W27:W34) | X35: =SUM(X27:X34) | Y35: =SUM(Y27:Y34) | Z35: =SUM(Z27:Z34) | AA35: =SUM(AA27:AA34) | ... CA35: =SUM(CA27:CA34)
G37: Direct Expenses
H38: =i_Setup!U75 | I38: =i_Setup!$M$16 | M38: =SUMIF($T$4:$CA$4,M$4,$T38:$CA38) | N38: =SUMIF($T$4:$CA$4,N$4,$T38:$CA38) | O38: =SUMIF($T$4:$CA$4,O$4,$T38:$CA38) | P38: =SUMIF($T$4:$CA$4,P$4,$T38:$CA38) | Q38: =SUMIF($T$4:$CA$4,Q$4,$T38:$CA38)
H39: =i_Setup!U76 | I39: =i_Setup!$M$16 | M39: =SUMIF($T$4:$CA$4,M$4,$T39:$CA39) | N39: =SUMIF($T$4:$CA$4,N$4,$T39:$CA39) | O39: =SUMIF($T$4:$CA$4,O$4,$T39:$CA39) | P39: =SUMIF($T$4:$CA$4,P$4,$T39:$CA39) | Q39: =SUMIF($T$4:$CA$4,Q$4,$T39:$CA39)
H40: =i_Setup!U77 | I40: =i_Setup!$M$16 | M40: =SUMIF($T$4:$CA$4,M$4,$T40:$CA40) | N40: =SUMIF($T$4:$CA$4,N$4,$T40:$CA40) | O40: =SUMIF($T$4:$CA$4,O$4,$T40:$CA40) | P40: =SUMIF($T$4:$CA$4,P$4,$T40:$CA40) | Q40: =SUMIF($T$4:$CA$4,Q$4,$T40:$CA40)
H41: =i_Setup!U78 | I41: =i_Setup!$M$16 | M41: =SUMIF($T$4:$CA$4,M$4,$T41:$CA41) | N41: =SUMIF($T$4:$CA$4,N$4,$T41:$CA41) | O41: =SUMIF($T$4:$CA$4,O$4,$T41:$CA41) | P41: =SUMIF($T$4:$CA$4,P$4,$T41:$CA41) | Q41: =SUMIF($T$4:$CA$4,Q$4,$T41:$CA41)
H42: =i_Setup!U79 | I42: =i_Setup!$M$16 | M42: =SUMIF($T$4:$CA$4,M$4,$T42:$CA42) | N42: =SUMIF($T$4:$CA$4,N$4,$T42:$CA42) | O42: =SUMIF($T$4:$CA$4,O$4,$T42:$CA42) | P42: =SUMIF($T$4:$CA$4,P$4,$T42:$CA42) | Q42: =SUMIF($T$4:$CA$4,Q$4,$T42:$CA42)
H43: =i_Setup!U80 | I43: =i_Setup!$M$16 | M43: =SUMIF($T$4:$CA$4,M$4,$T43:$CA43) | N43: =SUMIF($T$4:$CA$4,N$4,$T43:$CA43) | O43: =SUMIF($T$4:$CA$4,O$4,$T43:$CA43) | P43: =SUMIF($T$4:$CA$4,P$4,$T43:$CA43) | Q43: =SUMIF($T$4:$CA$4,Q$4,$T43:$CA43)
H44: =i_Setup!U81 | I44: =i_Setup!$M$16 | M44: =SUMIF($T$4:$CA$4,M$4,$T44:$CA44) | N44: =SUMIF($T$4:$CA$4,N$4,$T44:$CA44) | O44: =SUMIF($T$4:$CA$4,O$4,$T44:$CA44) | P44: =SUMIF($T$4:$CA$4,P$4,$T44:$CA44) | Q44: =SUMIF($T$4:$CA$4,Q$4,$T44:$CA44)
H45: =i_Setup!U82 | I45: =i_Setup!$M$16 | M45: =SUMIF($T$4:$CA$4,M$4,$T45:$CA45) | N45: =SUMIF($T$4:$CA$4,N$4,$T45:$CA45) | O45: =SUMIF($T$4:$CA$4,O$4,$T45:$CA45) | P45: =SUMIF($T$4:$CA$4,P$4,$T45:$CA45) | Q45: =SUMIF($T$4:$CA$4,Q$4,$T45:$CA45)
...

Sheet i_Assumptions
B1: =i_Setup!$M$13&" Financial Projection" | K1: Start date | M1: =DATE(i_Setup!$M$19,1,1) | N1: =M2+1 | O1: =N2+1 | P1: =O2+1 | Q1: =P2+1 | T1: =DATE(i_Setup!$M$19,1,1) | U1: =T2+1 | V1: =U2+1 | W1: =V2+1 | X1: =W2+1 | Y1: =X2+1 | Z1: =Y2+1 | AA1: =Z2+1 | AB1: =AA2+1 | ... CA1: =BZ2+1
B2: =MID(CELL("filename",C1),FIND("]",CELL("filename",C1))+1,256) | K2: End date | M2: =EDATE(M$1,12)-1 | N2: =EDATE(N$1,12)-1 | O2: =EDATE(O$1,12)-1 | P2: =EDATE(P$1,12)-1 | Q2: =EDATE(Q$1,12)-1 | T2: =EDATE(T$1,1)-1 | U2: =EDATE(U$1,1)-1 | V2: =EDATE(V$1,1)-1 | W2: =EDATE(W$1,1)-1 | X2: =EDATE(X$1,1)-1 | Y2: =EDATE(Y$1,1)-1 | Z2: =EDATE(Z$1,1)-1 | AA2: =EDATE(AA$1,1)-1 | ... CA2: =EDATE(CA$1,1)-1
K3: Timeline | M3: ANNUAL | N3: ANNUAL | O3: ANNUAL | P3: ANNUAL | Q3: ANNUAL | T3: MONTHLY | U3: MONTHLY | V3: MONTHLY | W3: MONTHLY | X3: MONTHLY | Y3: MONTHLY | Z3: MONTHLY | AA3: MONTHLY | AB3: MONTHLY | AC3: MONTHLY | AD3: MONTHLY | AE3: MONTHLY | AF3: MONTHLY | AG3: MONTHLY | AH3: MONTHLY | AI3: MONTHLY | AJ3: MONTHLY | AK3: MONTHLY | AL3: MONTHLY | AM3: MONTHLY | AN3: MONTHLY | AO3: MONTHLY | AP3: MONTHLY | AQ3: MONTHLY | AR3: MONTHLY | AS3: MONTHLY | AT3: MONTHLY | AU3: MONTHLY | AV3: MONTHLY | AW3: MONTHLY | AX3: MONTHLY | AY3: MONTHLY | AZ3: MONTHLY | BA3: MONTHLY | BB3: MONTHLY | BC3: MONTHLY | BD3: MONTHLY | BE3: MONTHLY | BF3: MONTHLY | BG3: MONTHLY | BH3: MONTHLY | BI3: MONTHLY | BJ3: MONTHLY | BK3: MONTHLY | BL3: MONTHLY | BM3: MONTHLY | BN3: MONTHLY | BO3: MONTHLY | BP3: MONTHLY | BQ3: MONTHLY | BR3: MONTHLY | BS3: MONTHLY | BT3: MONTHLY | BU3: MONTHLY | BV3: MONTHLY | BW3: MONTHLY | BX3: MONTHLY | BY3: MONTHLY | BZ3: MONTHLY | CA3: MONTHLY
B4: Tab Check | H4: LINK TO FRONT SHEET | K4: Year index | M4: 1 | N4: =M$4+1 | O4: =N$4+1 | P4: =O$4+1 | Q4: =P$4+1 | T4: =YEAR(T2)-(YEAR($M$1)-1) | U4: =YEAR(U2)-(YEAR($M$1)-1) | V4: =YEAR(V2)-(YEAR($M$1)-1) | W4: =YEAR(W2)-(YEAR($M$1)-1) | X4: =YEAR(X2)-(YEAR($M$1)-1) | Y4: =YEAR(Y2)-(YEAR($M$1)-1) | Z4: =YEAR(Z2)-(YEAR($M$1)-1) | AA4: =YEAR(AA2)-(YEAR($M$1)-1) | ... CA4: =YEAR(CA2)-(YEAR($M$1)-1)
B5: =SUM(B$9:B678) | C5: =SUM(C$9:C678) | H5: =sysCheckText | K5: Relative period | M5: 1 | N5: 1 | O5: 1 | P5: 1 | Q5: 1 | T5: =MONTH(T2) | U5: =MONTH(U2) | V5: =MONTH(V2) | W5: =MONTH(W2) | X5: =MONTH(X2) | Y5: =MONTH(Y2) | Z5: =MONTH(Z2) | AA5: =MONTH(AA2) | ... CA5: =MONTH(CA2)
B6: Err | C6: Alert | K6: Period index | M6: 1 | N6: =M$6+1 | O6: =N$6+1 | P6: =O$6+1 | Q6: =P$6+1 | T6: 1 | U6: =T$6+1 | V6: =U$6+1 | W6: =V$6+1 | X6: =W$6+1 | Y6: =X$6+1 | Z6: =Y$6+1 | AA6: =Z$6+1 | AB6: =AA$6+1 | ... CA6: =BZ$6+1
K7: Status | M7: =IF(M2<i_Setup!$U$25,"Actual","Forecast") | N7: =IF(N2<i_Setup!$U$25,"Actual","Forecast") | O7: =IF(O2<i_Setup!$U$25,"Actual","Forecast") | P7: =IF(P2<i_Setup!$U$25,"Actual","Forecast") | Q7: =IF(Q2<i_Setup!$U$25,"Actual","Forecast") | T7: =IF(T2<i_Setup!$U$25,"Actual","Forecast") | U7: =IF(U2<i_Setup!$U$25,"Actual","Forecast") | V7: =IF(V2<i_Setup!$U$25,"Actual","Forecast") | W7: =IF(W2<i_Setup!$U$25,"Actual","Forecast") | X7: =IF(X2<i_Setup!$U$25,"Actual","Forecast") | Y7: =IF(Y2<i_Setup!$U$25,"Actual","Forecast") | Z7: =IF(Z2<i_Setup!$U$25,"Actual","Forecast") | AA7: =IF(AA2<i_Setup!$U$25,"Actual","Forecast") | ... CA7: =IF(CA2<i_Setup!$U$25,"Actual","Forecast")
D9: =Heading1 | E9: Revenues
E11: =Heading2 | F11: Service Revenue
G13: Number of Ships
K14: Input:
H15: =i_Setup!U32 | I15: no. | K15: Annual | M15: 6 | N15: 7 | O15: 8 | P15: 8 | Q15: 8
H16: =i_Setup!U33 | I16: no. | K16: Annual | M16: 5 | N16: 5 | O16: 6 | P16: 6 | Q16: 6
H17: =i_Setup!U34 | I17: no. | K17: Annual | M17: 4 | N17: 5 | O17: 6 | P17: 6 | Q17: 6
H18: =i_Setup!U35 | I18: no. | K18: Annual | M18: 2 | N18: 2 | O18: 2 | P18: 2 | Q18: 2
H19: =i_Setup!U36 | I19: no. | K19: Annual | M19: 1 | N19: 1 | O19: 1 | P19: 1 | Q19: 1
H20: =i_Setup!U37 | I20: no. | K20: Annual
H21: =i_Setup!U38 | I21: no. | K21: Annual
H22: =i_Setup!U39 | I22: no. | K22: Annual
H23: =i_Setup!U40 | I23: no. | K23: Annual
H24: =i_Setup!U41 | I24: no. | K24: Annual
G27: Service Rate per Month per Ship (Excl VAT)
H29: =H15 | I29: =i_Setup!$M$16 | M29: 50000 | N29: =M29*1.05 | O29: =N29*1.05 | P29: =O29*1.05 | Q29: =P29*1.05
H30: =H16 | I30: =i_Setup!$M$16 | M30: 40000 | N30: =M30*1.05 | O30: =N30*1.05 | P30: =O30*1.05 | Q30: =P30*1.05
H31: =H17 | I31: =i_Setup!$M$16 | M31: 70000 | N31: =M31*1.05 | O31: =N31*1.05 | P31: =O31*1.05 | Q31: =P31*1.05
H32: =H18 | I32: =i_Setup!$M$16 | M32: 30000 | N32: =M32*1.05 | O32: =N32*1.05 | P32: =O32*1.05 | Q32: =P32*1.05
H33: =H19 | I33: =i_Setup!$M$16 | M33: 85000 | N33: =M33*1.05 | O33: =N33*1.05 | P33: =O33*1.05 | Q33: =P33*1.05
H34: =H20 | I34: =i_Setup!$M$16
H35: =H21 | I35: =i_Setup!$M$16
H36: =H22 | I36: =i_Setup!$M$16
H37: =H23 | I37: =i_Setup!$M$16
H38: =H24 | I38: =i_Setup!$M$16
G41: Average Credit Terms Offered
H43: =H29 | I43: Months | K43: 1
H44: =H30 | I44: Months | K44: 1
H45: =H31 | I45: Months | K45: 1
H46: =H32 | I46: Months | K46: 1
H47: =H33 | I47: Months | K47: 1
H48: =H34 | I48: Months | K48: 1
H49: =H35 | I49: Months | K49: 1
...

Sheet c_Calculations
B1: =i_Setup!$M$13&" Financial Projection" | K1: Start date | M1: =DATE(i_Setup!$M$19,1,1) | N1: =M2+1 | O1: =N2+1 | P1: =O2+1 | Q1: =P2+1 | T1: =DATE(i_Setup!$M$19,1,1) | U1: =T2+1 | V1: =U2+1 | W1: =V2+1 | X1: =W2+1 | Y1: =X2+1 | Z1: =Y2+1 | AA1: =Z2+1 | AB1: =AA2+1 | ... GQ1: =GP2+1
B2: =MID(CELL("filename",C1),FIND("]",CELL("filename",C1))+1,256) | K2: End date | M2: =EDATE(M$1,12)-1 | N2: =EDATE(N$1,12)-1 | O2: =EDATE(O$1,12)-1 | P2: =EDATE(P$1,12)-1 | Q2: =EDATE(Q$1,12)-1 | T2: =EDATE(T$1,1)-1 | U2: =EDATE(U$1,1)-1 | V2: =EDATE(V$1,1)-1 | W2: =EDATE(W$1,1)-1 | X2: =EDATE(X$1,1)-1 | Y2: =EDATE(Y$1,1)-1 | Z2: =EDATE(Z$1,1)-1 | AA2: =EDATE(AA$1,1)-1 | ... GQ2: =EDATE(GQ$1,1)-1
K3: Timeline | M3: ANNUAL | N3: ANNUAL | O3: ANNUAL | P3: ANNUAL | Q3: ANNUAL | T3: MONTHLY | U3: MONTHLY | V3: MONTHLY | W3: MONTHLY | X3: MONTHLY | Y3: MONTHLY | Z3: MONTHLY | AA3: MONTHLY | AB3: MONTHLY | AC3: MONTHLY | AD3: MONTHLY | AE3: MONTHLY | AF3: MONTHLY | AG3: MONTHLY | AH3: MONTHLY | AI3: MONTHLY | AJ3: MONTHLY | AK3: MONTHLY | AL3: MONTHLY | AM3: MONTHLY | AN3: MONTHLY | AO3: MONTHLY | AP3: MONTHLY | AQ3: MONTHLY | AR3: MONTHLY | AS3: MONTHLY | AT3: MONTHLY | AU3: MONTHLY | AV3: MONTHLY | AW3: MONTHLY | AX3: MONTHLY | AY3: MONTHLY | AZ3: MONTHLY | BA3: MONTHLY | BB3: MONTHLY | BC3: MONTHLY | BD3: MONTHLY | BE3: MONTHLY | BF3: MONTHLY | BG3: MONTHLY | BH3: MONTHLY | BI3: MONTHLY | BJ3: MONTHLY | BK3: MONTHLY | BL3: MONTHLY | BM3: MONTHLY | BN3: MONTHLY | BO3: MONTHLY | BP3: MONTHLY | BQ3: MONTHLY | BR3: MONTHLY | BS3: MONTHLY | BT3: MONTHLY | BU3: MONTHLY | BV3: MONTHLY | BW3: MONTHLY | BX3: MONTHLY | BY3: MONTHLY | BZ3: MONTHLY | CA3: MONTHLY | CB3: MONTHLY | CC3: MONTHLY | CD3: MONTHLY | CE3: MONTHLY | CF3: MONTHLY | CG3: MONTHLY | CH3: MONTHLY | CI3: MONTHLY | CJ3: MONTHLY | CK3: MONTHLY | CL3: MONTHLY | CM3: MONTHLY | CN3: MONTHLY | CO3: MONTHLY | CP3: MONTHLY | CQ3: MONTHLY | CR3: MONTHLY | CS3: MONTHLY | CT3: MONTHLY | CU3: MONTHLY | CV3: MONTHLY | CW3: MONTHLY | CX3: MONTHLY | CY3: MONTHLY | CZ3: MONTHLY | DA3: MONTHLY | DB3: MONTHLY | DC3: MONTHLY | DD3: MONTHLY | DE3: MONTHLY | DF3: MONTHLY | DG3: MONTHLY | DH3: MONTHLY | DI3: MONTHLY | DJ3: MONTHLY | DK3: MONTHLY | DL3: MONTHLY | DM3: MONTHLY | DN3: MONTHLY | DO3: MONTHLY | DP3: MONTHLY | DQ3: MONTHLY | DR3: MONTHLY | DS3: MONTHLY | DT3: MONTHLY | DU3: MONTHLY | DV3: MONTHLY | DW3: MONTHLY | DX3: MONTHLY | DY3: MONTHLY | DZ3: MONTHLY | EA3: MONTHLY | EB3: MONTHLY | EC3: MONTHLY | ED3: MONTHLY | EE3: MONTHLY | EF3: MONTHLY | EG3: MONTHLY | EH3: MONTHLY | EI3: MONTHLY | EJ3: MONTHLY | EK3: MONTHLY | EL3: MONTHLY | EM3: MONTHLY | EN3: MONTHLY | EO3: MONTHLY | EP3: MONTHLY | EQ3: MONTHLY | ER3: MONTHLY | ES3: MONTHLY | ET3: MONTHLY | EU3: MONTHLY | EV3: MONTHLY | EW3: MONTHLY | EX3: MONTHLY | EY3: MONTHLY | EZ3: MONTHLY | FA3: MONTHLY | FB3: MONTHLY | FC3: MONTHLY | FD3: MONTHLY | FE3: MONTHLY | FF3: MONTHLY | FG3: MONTHLY | FH3: MONTHLY | FI3: MONTHLY | FJ3: MONTHLY | FK3: MONTHLY | FL3: MONTHLY | FM3: MONTHLY | FN3: MONTHLY | FO3: MONTHLY | FP3: MONTHLY | FQ3: MONTHLY | FR3: MONTHLY | FS3: MONTHLY | FT3: MONTHLY | FU3: MONTHLY | FV3: MONTHLY | FW3: MONTHLY | FX3: MONTHLY | FY3: MONTHLY | FZ3: MONTHLY | GA3: MONTHLY | GB3: MONTHLY | GC3: MONTHLY | GD3: MONTHLY | GE3: MONTHLY | GF3: MONTHLY | GG3: MONTHLY | GH3: MONTHLY | GI3: MONTHLY | GJ3: MONTHLY | GK3: MONTHLY | GL3: MONTHLY | GM3: MONTHLY | GN3: MONTHLY | GO3: MONTHLY | GP3: MONTHLY | GQ3: MONTHLY
B4: Tab Check | H4: LINK TO FRONT SHEET | K4: Year index | M4: 1 | N4: =M$4+1 | O4: =N$4+1 | P4: =O$4+1 | Q4: =P$4+1 | T4: =YEAR(T2)-(YEAR($M$1)-1) | U4: =YEAR(U2)-(YEAR($M$1)-1) | V4: =YEAR(V2)-(YEAR($M$1)-1) | W4: =YEAR(W2)-(YEAR($M$1)-1) | X4: =YEAR(X2)-(YEAR($M$1)-1) | Y4: =YEAR(Y2)-(YEAR($M$1)-1) | Z4: =YEAR(Z2)-(YEAR($M$1)-1) | AA4: =YEAR(AA2)-(YEAR($M$1)-1) | ... GQ4: =YEAR(GQ2)-(YEAR($M$1)-1)
B5: =SUM(B$9:B1010) | C5: =SUM(C$9:C1010) | H5: =sysCheckText | K5: Relative period | M5: 1 | N5: 1 | O5: 1 | P5: 1 | Q5: 1 | T5: =MONTH(T2) | U5: =MONTH(U2) | V5: =MONTH(V2) | W5: =MONTH(W2) | X5: =MONTH(X2) | Y5: =MONTH(Y2) | Z5: =MONTH(Z2) | AA5: =MONTH(AA2) | ... GQ5: =MONTH(GQ2)
B6: Err | C6: Alert | K6: Period index | M6: 1 | N6: =M$6+1 | O6: =N$6+1 | P6: =O$6+1 | Q6: =P$6+1 | T6: 1 | U6: =T$6+1 | V6: =U$6+1 | W6: =V$6+1 | X6: =W$6+1 | Y6: =X$6+1 | Z6: =Y$6+1 | AA6: =Z$6+1 | AB6: =AA$6+1 | ... GQ6: =GP$6+1
K7: Status | M7: =IF(M2<i_Setup!$U$25,"Actual","Forecast") | N7: =IF(N2<i_Setup!$U$25,"Actual","Forecast") | O7: =IF(O2<i_Setup!$U$25,"Actual","Forecast") | P7: =IF(P2<i_Setup!$U$25,"Actual","Forecast") | Q7: =IF(Q2<i_Setup!$U$25,"Actual","Forecast") | T7: =IF(T2<i_Setup!$U$25,"Actual","Forecast") | U7: =IF(U2<i_Setup!$U$25,"Actual","Forecast") | V7: =IF(V2<i_Setup!$U$25,"Actual","Forecast") | W7: =IF(W2<i_Setup!$U$25,"Actual","Forecast") | X7: =IF(X2<i_Setup!$U$25,"Actual","Forecast") | Y7: =IF(Y2<i_Setup!$U$25,"Actual","Forecast") | Z7: =IF(Z2<i_Setup!$U$25,"Actual","Forecast") | AA7: =IF(AA2<i_Setup!$U$25,"Actual","Forecast") | ... CA7: =IF(CA2<i_Setup!$U$25,"Actual","Forecast")
D9: =Heading1 | E9: Revenue
E11: =Heading2 | F11: Revenue
G13: Number of Ships
H15: =i_Setup!U32 | I15: no. | K15: =i_Assumptions!K15 | M15: =IF($K15="Monthly",0,i_Assumptions!M15) | N15: =IF($K15="Monthly",0,i_Assumptions!N15) | O15: =IF($K15="Monthly",0,i_Assumptions!O15) | P15: =IF($K15="Monthly",0,i_Assumptions!P15) | Q15: =IF($K15="Monthly",0,i_Assumptions!Q15) | T15: =IF(T$7="Actual",0,IF($K15="Monthly",i_Assumptions!T15,INDEX($M15:$Q15,,MATCH(T$4,$M$4:$Q$4,0)))) | U15: =IF(U$7="Actual",0,IF($K15="Monthly",i_Assumptions!U15,INDEX($M15:$Q15,,MATCH(U$4,$M$4:$Q$4,0)))) | V15: =IF(V$7="Actual",0,IF($K15="Monthly",i_Assumptions!V15,INDEX($M15:$Q15,,MATCH(V$4,$M$4:$Q$4,0)))) | W15: =IF(W$7="Actual",0,IF($K15="Monthly",i_Assumptions!W15,INDEX($M15:$Q15,,MATCH(W$4,$M$4:$Q$4,0)))) | X15: =IF(X$7="Actual",0,IF($K15="Monthly",i_Assumptions!X15,INDEX($M15:$Q15,,MATCH(X$4,$M$4:$Q$4,0)))) | Y15: =IF(Y$7="Actual",0,IF($K15="Monthly",i_Assumptions!Y15,INDEX($M15:$Q15,,MATCH(Y$4,$M$4:$Q$4,0)))) | Z15: =IF(Z$7="Actual",0,IF($K15="Monthly",i_Assumptions!Z15,INDEX($M15:$Q15,,MATCH(Z$4,$M$4:$Q$4,0)))) | AA15: =IF(AA$7="Actual",0,IF($K15="Monthly",i_Assumptions!AA15,INDEX($M15:$Q15,,MATCH(AA$4,$M$4:$Q$4,0)))) | ... CA15: =IF(CA$7="Actual",0,IF($K15="Monthly",i_Assumptions!CA15,INDEX($M15:$Q15,,MATCH(CA$4,$M$4:$Q$4,0))))
H16: =i_Setup!U33 | I16: no. | K16: =i_Assumptions!K16 | M16: =IF($K16="Monthly",0,i_Assumptions!M16) | N16: =IF($K16="Monthly",0,i_Assumptions!N16) | O16: =IF($K16="Monthly",0,i_Assumptions!O16) | P16: =IF($K16="Monthly",0,i_Assumptions!P16) | Q16: =IF($K16="Monthly",0,i_Assumptions!Q16) | T16: =IF(T$7="Actual",0,IF($K16="Monthly",i_Assumptions!T16,INDEX($M16:$Q16,,MATCH(T$4,$M$4:$Q$4,0)))) | U16: =IF(U$7="Actual",0,IF($K16="Monthly",i_Assumptions!U16,INDEX($M16:$Q16,,MATCH(U$4,$M$4:$Q$4,0)))) | V16: =IF(V$7="Actual",0,IF($K16="Monthly",i_Assumptions!V16,INDEX($M16:$Q16,,MATCH(V$4,$M$4:$Q$4,0)))) | W16: =IF(W$7="Actual",0,IF($K16="Monthly",i_Assumptions!W16,INDEX($M16:$Q16,,MATCH(W$4,$M$4:$Q$4,0)))) | X16: =IF(X$7="Actual",0,IF($K16="Monthly",i_Assumptions!X16,INDEX($M16:$Q16,,MATCH(X$4,$M$4:$Q$4,0)))) | Y16: =IF(Y$7="Actual",0,IF($K16="Monthly",i_Assumptions!Y16,INDEX($M16:$Q16,,MATCH(Y$4,$M$4:$Q$4,0)))) | Z16: =IF(Z$7="Actual",0,IF($K16="Monthly",i_Assumptions!Z16,INDEX($M16:$Q16,,MATCH(Z$4,$M$4:$Q$4,0)))) | AA16: =IF(AA$7="Actual",0,IF($K16="Monthly",i_Assumptions!AA16,INDEX($M16:$Q16,,MATCH(AA$4,$M$4:$Q$4,0)))) | ... CA16: =IF(CA$7="Actual",0,IF($K16="Monthly",i_Assumptions!CA16,INDEX($M16:$Q16,,MATCH(CA$4,$M$4:$Q$4,0))))
H17: =i_Setup!U34 | I17: no. | K17: =i_Assumptions!K17 | M17: =IF($K17="Monthly",0,i_Assumptions!M17) | N17: =IF($K17="Monthly",0,i_Assumptions!N17) | O17: =IF($K17="Monthly",0,i_Assumptions!O17) | P17: =IF($K17="Monthly",0,i_Assumptions!P17) | Q17: =IF($K17="Monthly",0,i_Assumptions!Q17) | T17: =IF(T$7="Actual",0,IF($K17="Monthly",i_Assumptions!T17,INDEX($M17:$Q17,,MATCH(T$4,$M$4:$Q$4,0)))) | U17: =IF(U$7="Actual",0,IF($K17="Monthly",i_Assumptions!U17,INDEX($M17:$Q17,,MATCH(U$4,$M$4:$Q$4,0)))) | V17: =IF(V$7="Actual",0,IF($K17="Monthly",i_Assumptions!V17,INDEX($M17:$Q17,,MATCH(V$4,$M$4:$Q$4,0)))) | W17: =IF(W$7="Actual",0,IF($K17="Monthly",i_Assumptions!W17,INDEX($M17:$Q17,,MATCH(W$4,$M$4:$Q$4,0)))) | X17: =IF(X$7="Actual",0,IF($K17="Monthly",i_Assumptions!X17,INDEX($M17:$Q17,,MATCH(X$4,$M$4:$Q$4,0)))) | Y17: =IF(Y$7="Actual",0,IF($K17="Monthly",i_Assumptions!Y17,INDEX($M17:$Q17,,MATCH(Y$4,$M$4:$Q$4,0)))) | Z17: =IF(Z$7="Actual",0,IF($K17="Monthly",i_Assumptions!Z17,INDEX($M17:$Q17,,MATCH(Z$4,$M$4:$Q$4,0)))) | AA17: =IF(AA$7="Actual",0,IF($K17="Monthly",i_Assumptions!AA17,INDEX($M17:$Q17,,MATCH(AA$4,$M$4:$Q$4,0)))) | ... CA17: =IF(CA$7="Actual",0,IF($K17="Monthly",i_Assumptions!CA17,INDEX($M17:$Q17,,MATCH(CA$4,$M$4:$Q$4,0))))
H18: =i_Setup!U35 | I18: no. | K18: =i_Assumptions!K18 | M18: =IF($K18="Monthly",0,i_Assumptions!M18) | N18: =IF($K18="Monthly",0,i_Assumptions!N18) | O18: =IF($K18="Monthly",0,i_Assumptions!O18) | P18: =IF($K18="Monthly",0,i_Assumptions!P18) | Q18: =IF($K18="Monthly",0,i_Assumptions!Q18) | T18: =IF(T$7="Actual",0,IF($K18="Monthly",i_Assumptions!T18,INDEX($M18:$Q18,,MATCH(T$4,$M$4:$Q$4,0)))) | U18: =IF(U$7="Actual",0,IF($K18="Monthly",i_Assumptions!U18,INDEX($M18:$Q18,,MATCH(U$4,$M$4:$Q$4,0)))) | V18: =IF(V$7="Actual",0,IF($K18="Monthly",i_Assumptions!V18,INDEX($M18:$Q18,,MATCH(V$4,$M$4:$Q$4,0)))) | W18: =IF(W$7="Actual",0,IF($K18="Monthly",i_Assumptions!W18,INDEX($M18:$Q18,,MATCH(W$4,$M$4:$Q$4,0)))) | X18: =IF(X$7="Actual",0,IF($K18="Monthly",i_Assumptions!X18,INDEX($M18:$Q18,,MATCH(X$4,$M$4:$Q$4,0)))) | Y18: =IF(Y$7="Actual",0,IF($K18="Monthly",i_Assumptions!Y18,INDEX($M18:$Q18,,MATCH(Y$4,$M$4:$Q$4,0)))) | Z18: =IF(Z$7="Actual",0,IF($K18="Monthly",i_Assumptions!Z18,INDEX($M18:$Q18,,MATCH(Z$4,$M$4:$Q$4,0)))) | AA18: =IF(AA$7="Actual",0,IF($K18="Monthly",i_Assumptions!AA18,INDEX($M18:$Q18,,MATCH(AA$4,$M$4:$Q$4,0)))) | ... CA18: =IF(CA$7="Actual",0,IF($K18="Monthly",i_Assumptions!CA18,INDEX($M18:$Q18,,MATCH(CA$4,$M$4:$Q$4,0))))
H19: =i_Setup!U36 | I19: no. | K19: =i_Assumptions!K19 | M19: =IF($K19="Monthly",0,i_Assumptions!M19) | N19: =IF($K19="Monthly",0,i_Assumptions!N19) | O19: =IF($K19="Monthly",0,i_Assumptions!O19) | P19: =IF($K19="Monthly",0,i_Assumptions!P19) | Q19: =IF($K19="Monthly",0,i_Assumptions!Q19) | T19: =IF(T$7="Actual",0,IF($K19="Monthly",i_Assumptions!T19,INDEX($M19:$Q19,,MATCH(T$4,$M$4:$Q$4,0)))) | U19: =IF(U$7="Actual",0,IF($K19="Monthly",i_Assumptions!U19,INDEX($M19:$Q19,,MATCH(U$4,$M$4:$Q$4,0)))) | V19: =IF(V$7="Actual",0,IF($K19="Monthly",i_Assumptions!V19,INDEX($M19:$Q19,,MATCH(V$4,$M$4:$Q$4,0)))) | W19: =IF(W$7="Actual",0,IF($K19="Monthly",i_Assumptions!W19,INDEX($M19:$Q19,,MATCH(W$4,$M$4:$Q$4,0)))) | X19: =IF(X$7="Actual",0,IF($K19="Monthly",i_Assumptions!X19,INDEX($M19:$Q19,,MATCH(X$4,$M$4:$Q$4,0)))) | Y19: =IF(Y$7="Actual",0,IF($K19="Monthly",i_Assumptions!Y19,INDEX($M19:$Q19,,MATCH(Y$4,$M$4:$Q$4,0)))) | Z19: =IF(Z$7="Actual",0,IF($K19="Monthly",i_Assumptions!Z19,INDEX($M19:$Q19,,MATCH(Z$4,$M$4:$Q$4,0)))) | AA19: =IF(AA$7="Actual",0,IF($K19="Monthly",i_Assumptions!AA19,INDEX($M19:$Q19,,MATCH(AA$4,$M$4:$Q$4,0)))) | ... CA19: =IF(CA$7="Actual",0,IF($K19="Monthly",i_Assumptions!CA19,INDEX($M19:$Q19,,MATCH(CA$4,$M$4:$Q$4,0))))
H20: =i_Setup!U37 | I20: no. | K20: =i_Assumptions!K20 | M20: =IF($K20="Monthly",0,i_Assumptions!M20) | N20: =IF($K20="Monthly",0,i_Assumptions!N20) | O20: =IF($K20="Monthly",0,i_Assumptions!O20) | P20: =IF($K20="Monthly",0,i_Assumptions!P20) | Q20: =IF($K20="Monthly",0,i_Assumptions!Q20) | T20: =IF(T$7="Actual",0,IF($K20="Monthly",i_Assumptions!T20,INDEX($M20:$Q20,,MATCH(T$4,$M$4:$Q$4,0)))) | U20: =IF(U$7="Actual",0,IF($K20="Monthly",i_Assumptions!U20,INDEX($M20:$Q20,,MATCH(U$4,$M$4:$Q$4,0)))) | V20: =IF(V$7="Actual",0,IF($K20="Monthly",i_Assumptions!V20,INDEX($M20:$Q20,,MATCH(V$4,$M$4:$Q$4,0)))) | W20: =IF(W$7="Actual",0,IF($K20="Monthly",i_Assumptions!W20,INDEX($M20:$Q20,,MATCH(W$4,$M$4:$Q$4,0)))) | X20: =IF(X$7="Actual",0,IF($K20="Monthly",i_Assumptions!X20,INDEX($M20:$Q20,,MATCH(X$4,$M$4:$Q$4,0)))) | Y20: =IF(Y$7="Actual",0,IF($K20="Monthly",i_Assumptions!Y20,INDEX($M20:$Q20,,MATCH(Y$4,$M$4:$Q$4,0)))) | Z20: =IF(Z$7="Actual",0,IF($K20="Monthly",i_Assumptions!Z20,INDEX($M20:$Q20,,MATCH(Z$4,$M$4:$Q$4,0)))) | AA20: =IF(AA$7="Actual",0,IF($K20="Monthly",i_Assumptions!AA20,INDEX($M20:$Q20,,MATCH(AA$4,$M$4:$Q$4,0)))) | ... CA20: =IF(CA$7="Actual",0,IF($K20="Monthly",i_Assumptions!CA20,INDEX($M20:$Q20,,MATCH(CA$4,$M$4:$Q$4,0))))
H21: =i_Setup!U38 | I21: no. | K21: =i_Assumptions!K21 | M21: =IF($K21="Monthly",0,i_Assumptions!M21) | N21: =IF($K21="Monthly",0,i_Assumptions!N21) | O21: =IF($K21="Monthly",0,i_Assumptions!O21) | P21: =IF($K21="Monthly",0,i_Assumptions!P21) | Q21: =IF($K21="Monthly",0,i_Assumptions!Q21) | T21: =IF(T$7="Actual",0,IF($K21="Monthly",i_Assumptions!T21,INDEX($M21:$Q21,,MATCH(T$4,$M$4:$Q$4,0)))) | U21: =IF(U$7="Actual",0,IF($K21="Monthly",i_Assumptions!U21,INDEX($M21:$Q21,,MATCH(U$4,$M$4:$Q$4,0)))) | V21: =IF(V$7="Actual",0,IF($K21="Monthly",i_Assumptions!V21,INDEX($M21:$Q21,,MATCH(V$4,$M$4:$Q$4,0)))) | W21: =IF(W$7="Actual",0,IF($K21="Monthly",i_Assumptions!W21,INDEX($M21:$Q21,,MATCH(W$4,$M$4:$Q$4,0)))) | X21: =IF(X$7="Actual",0,IF($K21="Monthly",i_Assumptions!X21,INDEX($M21:$Q21,,MATCH(X$4,$M$4:$Q$4,0)))) | Y21: =IF(Y$7="Actual",0,IF($K21="Monthly",i_Assumptions!Y21,INDEX($M21:$Q21,,MATCH(Y$4,$M$4:$Q$4,0)))) | Z21: =IF(Z$7="Actual",0,IF($K21="Monthly",i_Assumptions!Z21,INDEX($M21:$Q21,,MATCH(Z$4,$M$4:$Q$4,0)))) | AA21: =IF(AA$7="Actual",0,IF($K21="Monthly",i_Assumptions!AA21,INDEX($M21:$Q21,,MATCH(AA$4,$M$4:$Q$4,0)))) | ... CA21: =IF(CA$7="Actual",0,IF($K21="Monthly",i_Assumptions!CA21,INDEX($M21:$Q21,,MATCH(CA$4,$M$4:$Q$4,0))))
H22: =i_Setup!U39 | I22: no. | K22: =i_Assumptions!K22 | M22: =IF($K22="Monthly",0,i_Assumptions!M22) | N22: =IF($K22="Monthly",0,i_Assumptions!N22) | O22: =IF($K22="Monthly",0,i_Assumptions!O22) | P22: =IF($K22="Monthly",0,i_Assumptions!P22) | Q22: =IF($K22="Monthly",0,i_Assumptions!Q22) | T22: =IF(T$7="Actual",0,IF($K22="Monthly",i_Assumptions!T22,INDEX($M22:$Q22,,MATCH(T$4,$M$4:$Q$4,0)))) | U22: =IF(U$7="Actual",0,IF($K22="Monthly",i_Assumptions!U22,INDEX($M22:$Q22,,MATCH(U$4,$M$4:$Q$4,0)))) | V22: =IF(V$7="Actual",0,IF($K22="Monthly",i_Assumptions!V22,INDEX($M22:$Q22,,MATCH(V$4,$M$4:$Q$4,0)))) | W22: =IF(W$7="Actual",0,IF($K22="Monthly",i_Assumptions!W22,INDEX($M22:$Q22,,MATCH(W$4,$M$4:$Q$4,0)))) | X22: =IF(X$7="Actual",0,IF($K22="Monthly",i_Assumptions!X22,INDEX($M22:$Q22,,MATCH(X$4,$M$4:$Q$4,0)))) | Y22: =IF(Y$7="Actual",0,IF($K22="Monthly",i_Assumptions!Y22,INDEX($M22:$Q22,,MATCH(Y$4,$M$4:$Q$4,0)))) | Z22: =IF(Z$7="Actual",0,IF($K22="Monthly",i_Assumptions!Z22,INDEX($M22:$Q22,,MATCH(Z$4,$M$4:$Q$4,0)))) | AA22: =IF(AA$7="Actual",0,IF($K22="Monthly",i_Assumptions!AA22,INDEX($M22:$Q22,,MATCH(AA$4,$M$4:$Q$4,0)))) | ... CA22: =IF(CA$7="Actual",0,IF($K22="Monthly",i_Assumptions!CA22,INDEX($M22:$Q22,,MATCH(CA$4,$M$4:$Q$4,0))))
H23: =i_Setup!U40 | I23: no. | K23: =i_Assumptions!K23 | M23: =IF($K23="Monthly",0,i_Assumptions!M23) | N23: =IF($K23="Monthly",0,i_Assumptions!N23) | O23: =IF($K23="Monthly",0,i_Assumptions!O23) | P23: =IF($K23="Monthly",0,i_Assumptions!P23) | Q23: =IF($K23="Monthly",0,i_Assumptions!Q23) | T23: =IF(T$7="Actual",0,IF($K23="Monthly",i_Assumptions!T23,INDEX($M23:$Q23,,MATCH(T$4,$M$4:$Q$4,0)))) | U23: =IF(U$7="Actual",0,IF($K23="Monthly",i_Assumptions!U23,INDEX($M23:$Q23,,MATCH(U$4,$M$4:$Q$4,0)))) | V23: =IF(V$7="Actual",0,IF($K23="Monthly",i_Assumptions!V23,INDEX($M23:$Q23,,MATCH(V$4,$M$4:$Q$4,0)))) | W23: =IF(W$7="Actual",0,IF($K23="Monthly",i_Assumptions!W23,INDEX($M23:$Q23,,MATCH(W$4,$M$4:$Q$4,0)))) | X23: =IF(X$7="Actual",0,IF($K23="Monthly",i_Assumptions!X23,INDEX($M23:$Q23,,MATCH(X$4,$M$4:$Q$4,0)))) | Y23: =IF(Y$7="Actual",0,IF($K23="Monthly",i_Assumptions!Y23,INDEX($M23:$Q23,,MATCH(Y$4,$M$4:$Q$4,0)))) | Z23: =IF(Z$7="Actual",0,IF($K23="Monthly",i_Assumptions!Z23,INDEX($M23:$Q23,,MATCH(Z$4,$M$4:$Q$4,0)))) | AA23: =IF(AA$7="Actual",0,IF($K23="Monthly",i_Assumptions!AA23,INDEX($M23:$Q23,,MATCH(AA$4,$M$4:$Q$4,0)))) | ... CA23: =IF(CA$7="Actual",0,IF($K23="Monthly",i_Assumptions!CA23,INDEX($M23:$Q23,,MATCH(CA$4,$M$4:$Q$4,0))))
H24: =i_Setup!U41 | I24: no. | K24: =i_Assumptions!K24 | M24: =IF($K24="Monthly",0,i_Assumptions!M24) | N24: =IF($K24="Monthly",0,i_Assumptions!N24) | O24: =IF($K24="Monthly",0,i_Assumptions!O24) | P24: =IF($K24="Monthly",0,i_Assumptions!P24) | Q24: =IF($K24="Monthly",0,i_Assumptions!Q24) | T24: =IF(T$7="Actual",0,IF($K24="Monthly",i_Assumptions!T24,INDEX($M24:$Q24,,MATCH(T$4,$M$4:$Q$4,0)))) | U24: =IF(U$7="Actual",0,IF($K24="Monthly",i_Assumptions!U24,INDEX($M24:$Q24,,MATCH(U$4,$M$4:$Q$4,0)))) | V24: =IF(V$7="Actual",0,IF($K24="Monthly",i_Assumptions!V24,INDEX($M24:$Q24,,MATCH(V$4,$M$4:$Q$4,0)))) | W24: =IF(W$7="Actual",0,IF($K24="Monthly",i_Assumptions!W24,INDEX($M24:$Q24,,MATCH(W$4,$M$4:$Q$4,0)))) | X24: =IF(X$7="Actual",0,IF($K24="Monthly",i_Assumptions!X24,INDEX($M24:$Q24,,MATCH(X$4,$M$4:$Q$4,0)))) | Y24: =IF(Y$7="Actual",0,IF($K24="Monthly",i_Assumptions!Y24,INDEX($M24:$Q24,,MATCH(Y$4,$M$4:$Q$4,0)))) | Z24: =IF(Z$7="Actual",0,IF($K24="Monthly",i_Assumptions!Z24,INDEX($M24:$Q24,,MATCH(Z$4,$M$4:$Q$4,0)))) | AA24: =IF(AA$7="Actual",0,IF($K24="Monthly",i_Assumptions!AA24,INDEX($M24:$Q24,,MATCH(AA$4,$M$4:$Q$4,0)))) | ... CA24: =IF(CA$7="Actual",0,IF($K24="Monthly",i_Assumptions!CA24,INDEX($M24:$Q24,,MATCH(CA$4,$M$4:$Q$4,0))))
H25: Total | I25: no | M25: =SUM(M15:M24) | N25: =SUM(N15:N24) | O25: =SUM(O15:O24) | P25: =SUM(P15:P24) | Q25: =SUM(Q15:Q24) | T25: =SUM(T15:T24) | U25: =SUM(U15:U24) | V25: =SUM(V15:V24) | W25: =SUM(W15:W24) | X25: =SUM(X15:X24) | Y25: =SUM(Y15:Y24) | Z25: =SUM(Z15:Z24) | AA25: =SUM(AA15:AA24) | ... CA25: =SUM(CA15:CA24)
G28: Service Rate per Month per Ship (Excl VAT)
H30: =H15 | I30: =i_Setup!$M$16 | M30: =i_Assumptions!M29 | N30: =i_Assumptions!N29 | O30: =i_Assumptions!O29 | P30: =i_Assumptions!P29 | Q30: =i_Assumptions!Q29 | T30: =IF(T$7="Actual","",INDEX($M30:$Q30,,MATCH(T$4,$M$4:$Q$4,0))) | U30: =IF(U$7="Actual","",INDEX($M30:$Q30,,MATCH(U$4,$M$4:$Q$4,0))) | V30: =IF(V$7="Actual","",INDEX($M30:$Q30,,MATCH(V$4,$M$4:$Q$4,0))) | W30: =IF(W$7="Actual","",INDEX($M30:$Q30,,MATCH(W$4,$M$4:$Q$4,0))) | X30: =IF(X$7="Actual","",INDEX($M30:$Q30,,MATCH(X$4,$M$4:$Q$4,0))) | Y30: =IF(Y$7="Actual","",INDEX($M30:$Q30,,MATCH(Y$4,$M$4:$Q$4,0))) | Z30: =IF(Z$7="Actual","",INDEX($M30:$Q30,,MATCH(Z$4,$M$4:$Q$4,0))) | AA30: =IF(AA$7="Actual","",INDEX($M30:$Q30,,MATCH(AA$4,$M$4:$Q$4,0))) | ... CA30: =IF(CA$7="Actual","",INDEX($M30:$Q30,,MATCH(CA$4,$M$4:$Q$4,0)))
H31: =H16 | I31: =i_Setup!$M$16 | M31: =i_Assumptions!M30 | N31: =i_Assumptions!N30 | O31: =i_Assumptions!O30 | P31: =i_Assumptions!P30 | Q31: =i_Assumptions!Q30 | T31: =IF(T$7="Actual","",INDEX($M31:$Q31,,MATCH(T$4,$M$4:$Q$4,0))) | U31: =IF(U$7="Actual","",INDEX($M31:$Q31,,MATCH(U$4,$M$4:$Q$4,0))) | V31: =IF(V$7="Actual","",INDEX($M31:$Q31,,MATCH(V$4,$M$4:$Q$4,0))) | W31: =IF(W$7="Actual","",INDEX($M31:$Q31,,MATCH(W$4,$M$4:$Q$4,0))) | X31: =IF(X$7="Actual","",INDEX($M31:$Q31,,MATCH(X$4,$M$4:$Q$4,0))) | Y31: =IF(Y$7="Actual","",INDEX($M31:$Q31,,MATCH(Y$4,$M$4:$Q$4,0))) | Z31: =IF(Z$7="Actual","",INDEX($M31:$Q31,,MATCH(Z$4,$M$4:$Q$4,0))) | AA31: =IF(AA$7="Actual","",INDEX($M31:$Q31,,MATCH(AA$4,$M$4:$Q$4,0))) | ... CA31: =IF(CA$7="Actual","",INDEX($M31:$Q31,,MATCH(CA$4,$M$4:$Q$4,0)))
H32: =H17 | I32: =i_Setup!$M$16 | M32: =i_Assumptions!M31 | N32: =i_Assumptions!N31 | O32: =i_Assumptions!O31 | P32: =i_Assumptions!P31 | Q32: =i_Assumptions!Q31 | T32: =IF(T$7="Actual","",INDEX($M32:$Q32,,MATCH(T$4,$M$4:$Q$4,0))) | U32: =IF(U$7="Actual","",INDEX($M32:$Q32,,MATCH(U$4,$M$4:$Q$4,0))) | V32: =IF(V$7="Actual","",INDEX($M32:$Q32,,MATCH(V$4,$M$4:$Q$4,0))) | W32: =IF(W$7="Actual","",INDEX($M32:$Q32,,MATCH(W$4,$M$4:$Q$4,0))) | X32: =IF(X$7="Actual","",INDEX($M32:$Q32,,MATCH(X$4,$M$4:$Q$4,0))) | Y32: =IF(Y$7="Actual","",INDEX($M32:$Q32,,MATCH(Y$4,$M$4:$Q$4,0))) | Z32: =IF(Z$7="Actual","",INDEX($M32:$Q32,,MATCH(Z$4,$M$4:$Q$4,0))) | AA32: =IF(AA$7="Actual","",INDEX($M32:$Q32,,MATCH(AA$4,$M$4:$Q$4,0))) | ... CA32: =IF(CA$7="Actual","",INDEX($M32:$Q32,,MATCH(CA$4,$M$4:$Q$4,0)))
H33: =H18 | I33: =i_Setup!$M$16 | M33: =i_Assumptions!M32 | N33: =i_Assumptions!N32 | O33: =i_Assumptions!O32 | P33: =i_Assumptions!P32 | Q33: =i_Assumptions!Q32 | T33: =IF(T$7="Actual","",INDEX($M33:$Q33,,MATCH(T$4,$M$4:$Q$4,0))) | U33: =IF(U$7="Actual","",INDEX($M33:$Q33,,MATCH(U$4,$M$4:$Q$4,0))) | V33: =IF(V$7="Actual","",INDEX($M33:$Q33,,MATCH(V$4,$M$4:$Q$4,0))) | W33: =IF(W$7="Actual","",INDEX($M33:$Q33,,MATCH(W$4,$M$4:$Q$4,0))) | X33: =IF(X$7="Actual","",INDEX($M33:$Q33,,MATCH(X$4,$M$4:$Q$4,0))) | Y33: =IF(Y$7="Actual","",INDEX($M33:$Q33,,MATCH(Y$4,$M$4:$Q$4,0))) | Z33: =IF(Z$7="Actual","",INDEX($M33:$Q33,,MATCH(Z$4,$M$4:$Q$4,0))) | AA33: =IF(AA$7="Actual","",INDEX($M33:$Q33,,MATCH(AA$4,$M$4:$Q$4,0))) | ... CA33: =IF(CA$7="Actual","",INDEX($M33:$Q33,,MATCH(CA$4,$M$4:$Q$4,0)))
H34: =H19 | I34: =i_Setup!$M$16 | M34: =i_Assumptions!M33 | N34: =i_Assumptions!N33 | O34: =i_Assumptions!O33 | P34: =i_Assumptions!P33 | Q34: =i_Assumptions!Q33 | T34: =IF(T$7="Actual","",INDEX($M34:$Q34,,MATCH(T$4,$M$4:$Q$4,0))) | U34: =IF(U$7="Actual","",INDEX($M34:$Q34,,MATCH(U$4,$M$4:$Q$4,0))) | V34: =IF(V$7="Actual","",INDEX($M34:$Q34,,MATCH(V$4,$M$4:$Q$4,0))) | W34: =IF(W$7="Actual","",INDEX($M34:$Q34,,MATCH(W$4,$M$4:$Q$4,0))) | X34: =IF(X$7="Actual","",INDEX($M34:$Q34,,MATCH(X$4,$M$4:$Q$4,0))) | Y34: =IF(Y$7="Actual","",INDEX($M34:$Q34,,MATCH(Y$4,$M$4:$Q$4,0))) | Z34: =IF(Z$7="Actual","",INDEX($M34:$Q34,,MATCH(Z$4,$M$4:$Q$4,0))) | AA34: =IF(AA$7="Actual","",INDEX($M34:$Q34,,MATCH(AA$4,$M$4:$Q$4,0))) | ... CA34: =IF(CA$7="Actual","",INDEX($M34:$Q34,,MATCH(CA$4,$M$4:$Q$4,0)))
H35: =H20 | I35: =i_Setup!$M$16 | M35: =i_Assumptions!M34 | N35: =i_Assumptions!N34 | O35: =i_Assumptions!O34 | P35: =i_Assumptions!P34 | Q35: =i_Assumptions!Q34 | T35: =IF(T$7="Actual","",INDEX($M35:$Q35,,MATCH(T$4,$M$4:$Q$4,0))) | U35: =IF(U$7="Actual","",INDEX($M35:$Q35,,MATCH(U$4,$M$4:$Q$4,0))) | V35: =IF(V$7="Actual","",INDEX($M35:$Q35,,MATCH(V$4,$M$4:$Q$4,0))) | W35: =IF(W$7="Actual","",INDEX($M35:$Q35,,MATCH(W$4,$M$4:$Q$4,0))) | X35: =IF(X$7="Actual","",INDEX($M35:$Q35,,MATCH(X$4,$M$4:$Q$4,0))) | Y35: =IF(Y$7="Actual","",INDEX($M35:$Q35,,MATCH(Y$4,$M$4:$Q$4,0))) | Z35: =IF(Z$7="Actual","",INDEX($M35:$Q35,,MATCH(Z$4,$M$4:$Q$4,0))) | AA35: =IF(AA$7="Actual","",INDEX($M35:$Q35,,MATCH(AA$4,$M$4:$Q$4,0))) | ... CA35: =IF(CA$7="Actual","",INDEX($M35:$Q35,,MATCH(CA$4,$M$4:$Q$4,0)))
H36: =H21 | I36: =i_Setup!$M$16 | M36: =i_Assumptions!M35 | N36: =i_Assumptions!N35 | O36: =i_Assumptions!O35 | P36: =i_Assumptions!P35 | Q36: =i_Assumptions!Q35 | T36: =IF(T$7="Actual","",INDEX($M36:$Q36,,MATCH(T$4,$M$4:$Q$4,0))) | U36: =IF(U$7="Actual","",INDEX($M36:$Q36,,MATCH(U$4,$M$4:$Q$4,0))) | V36: =IF(V$7="Actual","",INDEX($M36:$Q36,,MATCH(V$4,$M$4:$Q$4,0))) | W36: =IF(W$7="Actual","",INDEX($M36:$Q36,,MATCH(W$4,$M$4:$Q$4,0))) | X36: =IF(X$7="Actual","",INDEX($M36:$Q36,,MATCH(X$4,$M$4:$Q$4,0))) | Y36: =IF(Y$7="Actual","",INDEX($M36:$Q36,,MATCH(Y$4,$M$4:$Q$4,0))) | Z36: =IF(Z$7="Actual","",INDEX($M36:$Q36,,MATCH(Z$4,$M$4:$Q$4,0))) | AA36: =IF(AA$7="Actual","",INDEX($M36:$Q36,,MATCH(AA$4,$M$4:$Q$4,0))) | ... CA36: =IF(CA$7="Actual","",INDEX($M36:$Q36,,MATCH(CA$4,$M$4:$Q$4,0)))
H37: =H22 | I37: =i_Setup!$M$16 | M37: =i_Assumptions!M36 | N37: =i_Assumptions!N36 | O37: =i_Assumptions!O36 | P37: =i_Assumptions!P36 | Q37: =i_Assumptions!Q36 | T37: =IF(T$7="Actual","",INDEX($M37:$Q37,,MATCH(T$4,$M$4:$Q$4,0))) | U37: =IF(U$7="Actual","",INDEX($M37:$Q37,,MATCH(U$4,$M$4:$Q$4,0))) | V37: =IF(V$7="Actual","",INDEX($M37:$Q37,,MATCH(V$4,$M$4:$Q$4,0))) | W37: =IF(W$7="Actual","",INDEX($M37:$Q37,,MATCH(W$4,$M$4:$Q$4,0))) | X37: =IF(X$7="Actual","",INDEX($M37:$Q37,,MATCH(X$4,$M$4:$Q$4,0))) | Y37: =IF(Y$7="Actual","",INDEX($M37:$Q37,,MATCH(Y$4,$M$4:$Q$4,0))) | Z37: =IF(Z$7="Actual","",INDEX($M37:$Q37,,MATCH(Z$4,$M$4:$Q$4,0))) | AA37: =IF(AA$7="Actual","",INDEX($M37:$Q37,,MATCH(AA$4,$M$4:$Q$4,0))) | ... CA37: =IF(CA$7="Actual","",INDEX($M37:$Q37,,MATCH(CA$4,$M$4:$Q$4,0)))
H38: =H23 | I38: =i_Setup!$M$16 | M38: =i_Assumptions!M37 | N38: =i_Assumptions!N37 | O38: =i_Assumptions!O37 | P38: =i_Assumptions!P37 | Q38: =i_Assumptions!Q37 | T38: =IF(T$7="Actual","",INDEX($M38:$Q38,,MATCH(T$4,$M$4:$Q$4,0))) | U38: =IF(U$7="Actual","",INDEX($M38:$Q38,,MATCH(U$4,$M$4:$Q$4,0))) | V38: =IF(V$7="Actual","",INDEX($M38:$Q38,,MATCH(V$4,$M$4:$Q$4,0))) | W38: =IF(W$7="Actual","",INDEX($M38:$Q38,,MATCH(W$4,$M$4:$Q$4,0))) | X38: =IF(X$7="Actual","",INDEX($M38:$Q38,,MATCH(X$4,$M$4:$Q$4,0))) | Y38: =IF(Y$7="Actual","",INDEX($M38:$Q38,,MATCH(Y$4,$M$4:$Q$4,0))) | Z38: =IF(Z$7="Actual","",INDEX($M38:$Q38,,MATCH(Z$4,$M$4:$Q$4,0))) | AA38: =IF(AA$7="Actual","",INDEX($M38:$Q38,,MATCH(AA$4,$M$4:$Q$4,0))) | ... CA38: =IF(CA$7="Actual","",INDEX($M38:$Q38,,MATCH(CA$4,$M$4:$Q$4,0)))
H39: =H24 | I39: =i_Setup!$M$16 | M39: =i_Assumptions!M38 | N39: =i_Assumptions!N38 | O39: =i_Assumptions!O38 | P39: =i_Assumptions!P38 | Q39: =i_Assumptions!Q38 | T39: =IF(T$7="Actual","",INDEX($M39:$Q39,,MATCH(T$4,$M$4:$Q$4,0))) | U39: =IF(U$7="Actual","",INDEX($M39:$Q39,,MATCH(U$4,$M$4:$Q$4,0))) | V39: =IF(V$7="Actual","",INDEX($M39:$Q39,,MATCH(V$4,$M$4:$Q$4,0))) | W39: =IF(W$7="Actual","",INDEX($M39:$Q39,,MATCH(W$4,$M$4:$Q$4,0))) | X39: =IF(X$7="Actual","",INDEX($M39:$Q39,,MATCH(X$4,$M$4:$Q$4,0))) | Y39: =IF(Y$7="Actual","",INDEX($M39:$Q39,,MATCH(Y$4,$M$4:$Q$4,0))) | Z39: =IF(Z$7="Actual","",INDEX($M39:$Q39,,MATCH(Z$4,$M$4:$Q$4,0))) | AA39: =IF(AA$7="Actual","",INDEX($M39:$Q39,,MATCH(AA$4,$M$4:$Q$4,0))) | ... CA39: =IF(CA$7="Actual","",INDEX($M39:$Q39,,MATCH(CA$4,$M$4:$Q$4,0)))
G42: Total Revenue - Services (Excl Sales Tax)
H44: =H30 | I44: =i_Setup!$M$16 | M44: =SUMIF($T$4:$CA$4,M$4,$T44:$CA44) | N44: =SUMIF($T$4:$CA$4,N$4,$T44:$CA44) | O44: =SUMIF($T$4:$CA$4,O$4,$T44:$CA44) | P44: =SUMIF($T$4:$CA$4,P$4,$T44:$CA44) | Q44: =SUMIF($T$4:$CA$4,Q$4,$T44:$CA44) | T44: =IF(T$7="Actual","",T15*T30) | U44: =IF(U$7="Actual","",U15*U30) | V44: =IF(V$7="Actual","",V15*V30) | W44: =IF(W$7="Actual","",W15*W30) | X44: =IF(X$7="Actual","",X15*X30) | Y44: =IF(Y$7="Actual","",Y15*Y30) | Z44: =IF(Z$7="Actual","",Z15*Z30) | AA44: =IF(AA$7="Actual","",AA15*AA30) | ... CA44: =IF(CA$7="Actual","",CA15*CA30)
H45: =H31 | I45: =i_Setup!$M$16 | M45: =SUMIF($T$4:$CA$4,M$4,$T45:$CA45) | N45: =SUMIF($T$4:$CA$4,N$4,$T45:$CA45) | O45: =SUMIF($T$4:$CA$4,O$4,$T45:$CA45) | P45: =SUMIF($T$4:$CA$4,P$4,$T45:$CA45) | Q45: =SUMIF($T$4:$CA$4,Q$4,$T45:$CA45) | T45: =IF(T$7="Actual","",T16*T31) | U45: =IF(U$7="Actual","",U16*U31) | V45: =IF(V$7="Actual","",V16*V31) | W45: =IF(W$7="Actual","",W16*W31) | X45: =IF(X$7="Actual","",X16*X31) | Y45: =IF(Y$7="Actual","",Y16*Y31) | Z45: =IF(Z$7="Actual","",Z16*Z31) | AA45: =IF(AA$7="Actual","",AA16*AA31) | ... CA45: =IF(CA$7="Actual","",CA16*CA31)
H46: =H32 | I46: =i_Setup!$M$16 | M46: =SUMIF($T$4:$CA$4,M$4,$T46:$CA46) | N46: =SUMIF($T$4:$CA$4,N$4,$T46:$CA46) | O46: =SUMIF($T$4:$CA$4,O$4,$T46:$CA46) | P46: =SUMIF($T$4:$CA$4,P$4,$T46:$CA46) | Q46: =SUMIF($T$4:$CA$4,Q$4,$T46:$CA46) | T46: =IF(T$7="Actual","",T17*T32) | U46: =IF(U$7="Actual","",U17*U32) | V46: =IF(V$7="Actual","",V17*V32) | W46: =IF(W$7="Actual","",W17*W32) | X46: =IF(X$7="Actual","",X17*X32) | Y46: =IF(Y$7="Actual","",Y17*Y32) | Z46: =IF(Z$7="Actual","",Z17*Z32) | AA46: =IF(AA$7="Actual","",AA17*AA32) | ... CA46: =IF(CA$7="Actual","",CA17*CA32)
H47: =H33 | I47: =i_Setup!$M$16 | M47: =SUMIF($T$4:$CA$4,M$4,$T47:$CA47) | N47: =SUMIF($T$4:$CA$4,N$4,$T47:$CA47) | O47: =SUMIF($T$4:$CA$4,O$4,$T47:$CA47) | P47: =SUMIF($T$4:$CA$4,P$4,$T47:$CA47) | Q47: =SUMIF($T$4:$CA$4,Q$4,$T47:$CA47) | T47: =IF(T$7="Actual","",T18*T33) | U47: =IF(U$7="Actual","",U18*U33) | V47: =IF(V$7="Actual","",V18*V33) | W47: =IF(W$7="Actual","",W18*W33) | X47: =IF(X$7="Actual","",X18*X33) | Y47: =IF(Y$7="Actual","",Y18*Y33) | Z47: =IF(Z$7="Actual","",Z18*Z33) | AA47: =IF(AA$7="Actual","",AA18*AA33) | ... CA47: =IF(CA$7="Actual","",CA18*CA33)
H48: =H34 | I48: =i_Setup!$M$16 | M48: =SUMIF($T$4:$CA$4,M$4,$T48:$CA48) | N48: =SUMIF($T$4:$CA$4,N$4,$T48:$CA48) | O48: =SUMIF($T$4:$CA$4,O$4,$T48:$CA48) | P48: =SUMIF($T$4:$CA$4,P$4,$T48:$CA48) | Q48: =SUMIF($T$4:$CA$4,Q$4,$T48:$CA48) | T48: =IF(T$7="Actual","",T19*T34) | U48: =IF(U$7="Actual","",U19*U34) | V48: =IF(V$7="Actual","",V19*V34) | W48: =IF(W$7="Actual","",W19*W34) | X48: =IF(X$7="Actual","",X19*X34) | Y48: =IF(Y$7="Actual","",Y19*Y34) | Z48: =IF(Z$7="Actual","",Z19*Z34) | AA48: =IF(AA$7="Actual","",AA19*AA34) | ... CA48: =IF(CA$7="Actual","",CA19*CA34)
H49: =H35 | I49: =i_Setup!$M$16 | M49: =SUMIF($T$4:$CA$4,M$4,$T49:$CA49) | N49: =SUMIF($T$4:$CA$4,N$4,$T49:$CA49) | O49: =SUMIF($T$4:$CA$4,O$4,$T49:$CA49) | P49: =SUMIF($T$4:$CA$4,P$4,$T49:$CA49) | Q49: =SUMIF($T$4:$CA$4,Q$4,$T49:$CA49) | T49: =IF(T$7="Actual","",T20*T35) | U49: =IF(U$7="Actual","",U20*U35) | V49: =IF(V$7="Actual","",V20*V35) | W49: =IF(W$7="Actual","",W20*W35) | X49: =IF(X$7="Actual","",X20*X35) | Y49: =IF(Y$7="Actual","",Y20*Y35) | Z49: =IF(Z$7="Actual","",Z20*Z35) | AA49: =IF(AA$7="Actual","",AA20*AA35) | ... CA49: =IF(CA$7="Actual","",CA20*CA35)
H50: =H36 | I50: =i_Setup!$M$16 | M50: =SUMIF($T$4:$CA$4,M$4,$T50:$CA50) | N50: =SUMIF($T$4:$CA$4,N$4,$T50:$CA50) | O50: =SUMIF($T$4:$CA$4,O$4,$T50:$CA50) | P50: =SUMIF($T$4:$CA$4,P$4,$T50:$CA50) | Q50: =SUMIF($T$4:$CA$4,Q$4,$T50:$CA50) | T50: =IF(T$7="Actual","",T21*T36) | U50: =IF(U$7="Actual","",U21*U36) | V50: =IF(V$7="Actual","",V21*V36) | W50: =IF(W$7="Actual","",W21*W36) | X50: =IF(X$7="Actual","",X21*X36) | Y50: =IF(Y$7="Actual","",Y21*Y36) | Z50: =IF(Z$7="Actual","",Z21*Z36) | AA50: =IF(AA$7="Actual","",AA21*AA36) | ... CA50: =IF(CA$7="Actual","",CA21*CA36)
...

Sheet o_Fin Stats
B1: =i_Setup!$M$13&" Financial Projection" | K1: Start date | M1: =DATE(i_Setup!$M$19,1,1) | N1: =M2+1 | O1: =N2+1 | P1: =O2+1 | Q1: =P2+1 | T1: =DATE(i_Setup!$M$19,1,1) | U1: =T2+1 | V1: =U2+1 | W1: =V2+1 | X1: =W2+1 | Y1: =X2+1 | Z1: =Y2+1 | AA1: =Z2+1 | AB1: =AA2+1 | ... CA1: =BZ2+1
B2: =MID(CELL("filename",C1),FIND("]",CELL("filename",C1))+1,256) | K2: End date | M2: =EDATE(M$1,12)-1 | N2: =EDATE(N$1,12)-1 | O2: =EDATE(O$1,12)-1 | P2: =EDATE(P$1,12)-1 | Q2: =EDATE(Q$1,12)-1 | T2: =EDATE(T$1,1)-1 | U2: =EDATE(U$1,1)-1 | V2: =EDATE(V$1,1)-1 | W2: =EDATE(W$1,1)-1 | X2: =EDATE(X$1,1)-1 | Y2: =EDATE(Y$1,1)-1 | Z2: =EDATE(Z$1,1)-1 | AA2: =EDATE(AA$1,1)-1 | ... CA2: =EDATE(CA$1,1)-1
K3: Timeline | M3: ANNUAL | N3: ANNUAL | O3: ANNUAL | P3: ANNUAL | Q3: ANNUAL | T3: MONTHLY | U3: MONTHLY | V3: MONTHLY | W3: MONTHLY | X3: MONTHLY | Y3: MONTHLY | Z3: MONTHLY | AA3: MONTHLY | AB3: MONTHLY | AC3: MONTHLY | AD3: MONTHLY | AE3: MONTHLY | AF3: MONTHLY | AG3: MONTHLY | AH3: MONTHLY | AI3: MONTHLY | AJ3: MONTHLY | AK3: MONTHLY | AL3: MONTHLY | AM3: MONTHLY | AN3: MONTHLY | AO3: MONTHLY | AP3: MONTHLY | AQ3: MONTHLY | AR3: MONTHLY | AS3: MONTHLY | AT3: MONTHLY | AU3: MONTHLY | AV3: MONTHLY | AW3: MONTHLY | AX3: MONTHLY | AY3: MONTHLY | AZ3: MONTHLY | BA3: MONTHLY | BB3: MONTHLY | BC3: MONTHLY | BD3: MONTHLY | BE3: MONTHLY | BF3: MONTHLY | BG3: MONTHLY | BH3: MONTHLY | BI3: MONTHLY | BJ3: MONTHLY | BK3: MONTHLY | BL3: MONTHLY | BM3: MONTHLY | BN3: MONTHLY | BO3: MONTHLY | BP3: MONTHLY | BQ3: MONTHLY | BR3: MONTHLY | BS3: MONTHLY | BT3: MONTHLY | BU3: MONTHLY | BV3: MONTHLY | BW3: MONTHLY | BX3: MONTHLY | BY3: MONTHLY | BZ3: MONTHLY | CA3: MONTHLY
B4: Tab Check | H4: LINK TO FRONT SHEET | K4: Year index | M4: 1 | N4: =M$4+1 | O4: =N$4+1 | P4: =O$4+1 | Q4: =P$4+1 | T4: =YEAR(T2)-(YEAR($M$1)-1) | U4: =YEAR(U2)-(YEAR($M$1)-1) | V4: =YEAR(V2)-(YEAR($M$1)-1) | W4: =YEAR(W2)-(YEAR($M$1)-1) | X4: =YEAR(X2)-(YEAR($M$1)-1) | Y4: =YEAR(Y2)-(YEAR($M$1)-1) | Z4: =YEAR(Z2)-(YEAR($M$1)-1) | AA4: =YEAR(AA2)-(YEAR($M$1)-1) | ... CA4: =YEAR(CA2)-(YEAR($M$1)-1)
B5: =SUM(B$9:B207) | C5: =SUM(C$9:C207) | H5: =sysCheckText | K5: Relative period | M5: 1 | N5: 1 | O5: 1 | P5: 1 | Q5: 1 | T5: =MONTH(T2) | U5: =MONTH(U2) | V5: =MONTH(V2) | W5: =MONTH(W2) | X5: =MONTH(X2) | Y5: =MONTH(Y2) | Z5: =MONTH(Z2) | AA5: =MONTH(AA2) | ... CA5: =MONTH(CA2)
B6: Err | C6: Alert | K6: Period index | M6: 1 | N6: =M$6+1 | O6: =N$6+1 | P6: =O$6+1 | Q6: =P$6+1 | T6: 1 | U6: =T$6+1 | V6: =U$6+1 | W6: =V$6+1 | X6: =W$6+1 | Y6: =X$6+1 | Z6: =Y$6+1 | AA6: =Z$6+1 | AB6: =AA$6+1 | ... CA6: =BZ$6+1
K7: Status | M7: =IF(M2<i_Setup!$U$25,"Actual","Forecast") | N7: =IF(N2<i_Setup!$U$25,"Actual","Forecast") | O7: =IF(O2<i_Setup!$U$25,"Actual","Forecast") | P7: =IF(P2<i_Setup!$U$25,"Actual","Forecast") | Q7: =IF(Q2<i_Setup!$U$25,"Actual","Forecast") | T7: =IF(T2<i_Setup!$U$25,"Actual","Forecast") | U7: =IF(U2<i_Setup!$U$25,"Actual","Forecast") | V7: =IF(V2<i_Setup!$U$25,"Actual","Forecast") | W7: =IF(W2<i_Setup!$U$25,"Actual","Forecast") | X7: =IF(X2<i_Setup!$U$25,"Actual","Forecast") | Y7: =IF(Y2<i_Setup!$U$25,"Actual","Forecast") | Z7: =IF(Z2<i_Setup!$U$25,"Actual","Forecast") | AA7: =IF(AA2<i_Setup!$U$25,"Actual","Forecast") | ... CA7: =IF(CA2<i_Setup!$U$25,"Actual","Forecast")
D9: =Heading1 | E9: Income Statement
E11: =Heading2 | F11: Income Statement
G13: Total Revenue
H14: =i_Setup!U32 | I14: =i_Setup!$M$16 | M14: =SUMIF($T$4:$CA$4,M$4,$T14:$CA14) | N14: =SUMIF($T$4:$CA$4,N$4,$T14:$CA14) | O14: =SUMIF($T$4:$CA$4,O$4,$T14:$CA14) | P14: =SUMIF($T$4:$CA$4,P$4,$T14:$CA14) | Q14: =SUMIF($T$4:$CA$4,Q$4,$T14:$CA14) | T14: =IF(T$7="Actual",i_Actuals!T14,c_Calculations!T44) | U14: =IF(U$7="Actual",i_Actuals!U14,c_Calculations!U44) | V14: =IF(V$7="Actual",i_Actuals!V14,c_Calculations!V44) | W14: =IF(W$7="Actual",i_Actuals!W14,c_Calculations!W44) | X14: =IF(X$7="Actual",i_Actuals!X14,c_Calculations!X44) | Y14: =IF(Y$7="Actual",i_Actuals!Y14,c_Calculations!Y44) | Z14: =IF(Z$7="Actual",i_Actuals!Z14,c_Calculations!Z44) | AA14: =IF(AA$7="Actual",i_Actuals!AA14,c_Calculations!AA44) | ... CA14: =IF(CA$7="Actual",i_Actuals!CA14,c_Calculations!CA44)
H15: =i_Setup!U33 | I15: =i_Setup!$M$16 | M15: =SUMIF($T$4:$CA$4,M$4,$T15:$CA15) | N15: =SUMIF($T$4:$CA$4,N$4,$T15:$CA15) | O15: =SUMIF($T$4:$CA$4,O$4,$T15:$CA15) | P15: =SUMIF($T$4:$CA$4,P$4,$T15:$CA15) | Q15: =SUMIF($T$4:$CA$4,Q$4,$T15:$CA15) | T15: =IF(T$7="Actual",i_Actuals!T15,c_Calculations!T45) | U15: =IF(U$7="Actual",i_Actuals!U15,c_Calculations!U45) | V15: =IF(V$7="Actual",i_Actuals!V15,c_Calculations!V45) | W15: =IF(W$7="Actual",i_Actuals!W15,c_Calculations!W45) | X15: =IF(X$7="Actual",i_Actuals!X15,c_Calculations!X45) | Y15: =IF(Y$7="Actual",i_Actuals!Y15,c_Calculations!Y45) | Z15: =IF(Z$7="Actual",i_Actuals!Z15,c_Calculations!Z45) | AA15: =IF(AA$7="Actual",i_Actuals!AA15,c_Calculations!AA45) | ... CA15: =IF(CA$7="Actual",i_Actuals!CA15,c_Calculations!CA45)
H16: =i_Setup!U34 | I16: =i_Setup!$M$16 | M16: =SUMIF($T$4:$CA$4,M$4,$T16:$CA16) | N16: =SUMIF($T$4:$CA$4,N$4,$T16:$CA16) | O16: =SUMIF($T$4:$CA$4,O$4,$T16:$CA16) | P16: =SUMIF($T$4:$CA$4,P$4,$T16:$CA16) | Q16: =SUMIF($T$4:$CA$4,Q$4,$T16:$CA16) | T16: =IF(T$7="Actual",i_Actuals!T16,c_Calculations!T46) | U16: =IF(U$7="Actual",i_Actuals!U16,c_Calculations!U46) | V16: =IF(V$7="Actual",i_Actuals!V16,c_Calculations!V46) | W16: =IF(W$7="Actual",i_Actuals!W16,c_Calculations!W46) | X16: =IF(X$7="Actual",i_Actuals!X16,c_Calculations!X46) | Y16: =IF(Y$7="Actual",i_Actuals!Y16,c_Calculations!Y46) | Z16: =IF(Z$7="Actual",i_Actuals!Z16,c_Calculations!Z46) | AA16: =IF(AA$7="Actual",i_Actuals!AA16,c_Calculations!AA46) | ... CA16: =IF(CA$7="Actual",i_Actuals!CA16,c_Calculations!CA46)
